Workbook

Sheet בית
B1: כלכלת המשפחה — ניהול תזרים
B2: 5 שלבים, לפי הסדר. לחצו על שם השלב כדי לקפוץ אליו.
B4: תזרים החודש (ממוצע) | D4: כרית חירום (חודשים) | F4: % מהמטרות שממומן
B5: =IFERROR(IF(תזרים!$AC$2>0,תזרים!AB56/תזרים!$AC$2,תזרים!AA56/12),0) | D5: =IFERROR((N(מאזן!C6)+N(מאזן!C7))/MAX(1,IF(תזרים!$AC$2>0,תזרים!AB55/תזרים!$AC$2,תזרים!AA55/12)),0) | F5: =IFERROR('מטרות ויעדים'!K17/'מטרות ויעדים'!J17,0)
B7: 1 | C7: שאלון | D7: מי אתם + המטרות הגדולות. מזין את מטרות ויעדים.
B8: 2 | C8: מיפוי | D8: 3 חודשים אחורה — לאן הכסף באמת הולך. כולל מנויים וביטוחים.
B9: 3 | C9: חובות | D9: הלוואות ועסקאות בתשלומים — פעם אחת, זורם לתזרים.
B10: 4 | C10: מאזן | D10: מה יש ומה חייבים — השווי הנקי של המשפחה.
B11: 5 | C11: מטרות ויעדים | D11: החלומות: כמה צריך, כמה יש, כמה מפקידים.
B12: 6 | C12: תזרים | D12: התכנית קדימה: תכנון מול ביצוע, חודש בחודש.
B13: 7 | C13: סיכום שנתי | D13: המבט מלמעלה: רמזור, פילוח ומעקב שנים.
B14: תאריך תחילת הפעילות (חודש ראשון בתזרים): | C14: תובנות | D14: העמוד שמציגים לזוג — רמזור ותוכנית פעולה.
B15: 9 | C15: יומן ליווי | D15: מה סוכם בכל פגישה ומה המשימות.
B17: צהוב = ממלאים. כל השאר מחושב לבד. ממלאים מיפוי פעם אחת — והתזרים כבר בנוי.
B19: יש עסק? מסמנים בשאלון, ופותחים את לשונית עסק: קליק ימני על הלשוניות למטה ← הצג ← עסק.
D21: שנת פעילות: | E21: =תזרים!H2 | F21: =IF(C21="","← בוחרים חודש ושנה בעמוד התזרים, מתחת לכותרת","← שנת התזרים: "&YEAR(תזרים!C62))
B23: הקובץ מלווה את המשפחה שנים: בסוף כל שנה מעלים את "שנת פעילות" ב-1 (1→2), מעתיקים את השורה החיה בארכיון שבסיכום השנתי — וממשיכים באותו קובץ.

Sheet שאלון
B1: שאלון היכרות פיננסי | I1: 🏠 בית
B2: ממלאים ביחד בפגישה הראשונה. המטרות שבסוף יזינו אוטומטית את עמוד מטרות ויעדים.
B4: פרטים אישיים
C5: =IF(שאלון!$C$6="","בן/בת זוג 1",שאלון!$C$6) | D5: =IF(שאלון!$D$6="","בן/בת זוג 2",שאלון!$D$6) | E5: הערות
B6: שם מלא
B7: גיל
B8: סטטוס משפחתי
B9: עיסוק
B10: אופן העסקה (שכיר / עצמאי / בעל שליטה)
B11: טלפון / מייל
B12: מספר ילדים
B13: גילאי הילדים
B14: יש עסק עצמאי במשפחה? | D14: אם כן — פותחים את לשונית "עסק" (קליק ימני על הלשוניות ← הצג)
B16: פרטים פיננסיים — הערכה גסה, בלי לפתוח מסמכים
B17: דירת המגורים בבעלותכם?
B18: שווי הדירה להערכתכם
B19: שווי נכסים פנסיוניים (פנסיה, גמל, השתלמות)
B20: חסכונות והשקעות (שוק ההון, מזומן, פיקדונות)
B21: יתרת משכנתא
B22: יתרת הלוואות אחרות
B23: הכנסה חודשית נטו — משפחתית
B24: הוצאות חודשיות — להערכתכם
B26: ידע פיננסי וסיכון
C27: =IF(שאלון!$C$6="","בן/בת זוג 1",שאלון!$C$6) | D27: =IF(שאלון!$D$6="","בן/בת זוג 2",שאלון!$D$6) | E27: הערות
B28: רמת ידע בשוק ההון (מצוין/טוב/בינוני/אין)
B29: עד כמה אוהבים סיכון?
B30: איך תרגישו אם ההשקעות יירדו ב-30%?
B32: ביטוחים ומשפחה
C33: =IF(שאלון!$C$6="","בן/בת זוג 1",שאלון!$C$6) | D33: =IF(שאלון!$D$6="","בן/בת זוג 2",שאלון!$D$6) | E33: הערות
B34: ביטוח בריאות פרטי?
B35: סכום ביטוח חיים קיים (₪)
B36: בעיה בריאותית שכדאי לדעת עליה?
B37: קיימת צוואה / ייפוי כוח מתמשך?
B38: הורה תלוי (או עתיד להיות תלוי) כלכלית?
B40: תכנון וציפיות — השיחה האמיתית
B41: מה הכי מטריד אתכם בכסף היום?
B42: מה בראש סדר העדיפויות בזמן הקרוב?
B43: נושא דחוף שחייבים לטפל בו לפני הכל?
B44: מה הציפיות שלכם מהתהליך?
B45: מה יגרום לכם להרגיש בעוד חצי שנה שההחלטה היתה נכונה?
...

Sheet מיפוי
B1: מיפוי — 3 החודשים האחרונים | I1: 🏠 בית
B2: ממלאים מדפי הבנק והאשראי. הממוצע נהיה הבסיס לתזרים.
J3: מנויים
B4: הכנסות | J4: שם המנוי | K4: בית/עסק | L4: סכום חודשי
B5: קטגוריה | C5: סה"כ 3 חודשים | D5: ממוצע לחודש | E5: % מהכנסה | K5: בית
B6: ="משכורת "&IF(שאלון!$C$6="","בן/בת זוג 1",שאלון!$C$6) | D6: =IF(C6="","",C6/3) | E6: =IF(OR(D6="",D$12=0),"",D6/D$12) | K6: בית
B7: ="משכורת "&IF(שאלון!$D$6="","בן/בת זוג 2",שאלון!$D$6) | D7: =IF(C7="","",C7/3) | E7: =IF(OR(D7="",D$12=0),"",D7/D$12) | K7: בית
B8: קצבאות (ילדים) | D8: =IF(C8="","",C8/3) | E8: =IF(OR(D8="",D$12=0),"",D8/D$12) | K8: בית
B9: משכורת / משיכה מהעסק | D9: =IF(C9="","",C9/3) | E9: =IF(OR(D9="",D$12=0),"",D9/D$12) | K9: בית
B10: הכנסה נוספת | D10: =IF(C10="","",C10/3) | E10: =IF(OR(D10="",D$12=0),"",D10/D$12) | K10: בית
D11: =IF(C11="","",C11/3) | E11: =IF(OR(D11="",D$12=0),"",D11/D$12) | K11: בית
B12: סה"כ הכנסות | C12: =SUM(C6:C11) | D12: =SUM(D6:D11) | K12: בית
K13: בית
B14: הוצאות קבועות | K14: בית
B15: קטגוריה | C15: סה"כ 3 חודשים | D15: ממוצע לחודש | E15: % מהכנסה | K15: בית
B16: משכנתא / שכר דירה | C16: =IFERROR(חובות!C40*3,0) | D16: =IF(C16="","",C16/3) | E16: ← נמשך מדף חובות (ניתן לדרוס) | K16: בית
B17: ארנונה | D17: =IF(C17="","",C17/3) | E17: =IF(OR(D17="",D$12=0),"",D17/D$12) | J17: סה"כ בית (זורם לתזרים) | L17: =SUMIF(K5:K16,"בית",L5:L16)
B18: חשמל | D18: =IF(C18="","",C18/3) | E18: =IF(OR(D18="",D$12=0),"",D18/D$12) | J18: מזה עסק | L18: =SUMIF(K5:K16,"עסק",L5:L16)
B19: מים | D19: =IF(C19="","",C19/3) | E19: =IF(OR(D19="",D$12=0),"",D19/D$12)
B20: גז | D20: =IF(C20="","",C20/3) | E20: =IF(OR(D20="",D$12=0),"",D20/D$12) | J20: ביטוחים
B21: ועד בית | D21: =IF(C21="","",C21/3) | E21: =IF(OR(D21="",D$12=0),"",D21/D$12) | J21: שם הביטוח | K21: סכום חודשי
B22: תקשורת (סלולר, אינטרנט, טלוויזיה) | D22: =IF(C22="","",C22/3) | E22: =IF(OR(D22="",D$12=0),"",D22/D$12) | J22: ="ביטוח חיים — "&IF(שאלון!C6="","בן/בת זוג 1",שאלון!C6)
B23: ביטוחים | D23: =IF(C23="","",C23/3) | E23: =IF(OR(D23="",D$12=0),"",D23/D$12) | J23: ="ביטוח חיים — "&IF(שאלון!D6="","בן/בת זוג 2",שאלון!D6)
B24: מנויים | D24: =IF(C24="","",C24/3) | E24: =IF(OR(D24="",D$12=0),"",D24/D$12) | J24: ביטוח בריאות
B25: חינוך וחוגים | D25: =IF(C25="","",C25/3) | E25: =IF(OR(D25="",D$12=0),"",D25/D$12) | J25: אובדן כושר עבודה
B26: בריאות (קבוע) | D26: =IF(C26="","",C26/3) | E26: =IF(OR(D26="",D$12=0),"",D26/D$12) | J26: ביטוח סיעודי
B27: הפקדה לחיסכון | D27: =IF(C27="","",C27/3) | E27: =IF(OR(D27="",D$12=0),"",D27/D$12) | J27: ביטוח שיניים
B28: החזרי הלוואות | D28: =IF(C28="","",C28/3) | E28: =IF(OR(D28="",D$12=0),"",D28/D$12) | J28: ביטוח דירה / מבנה
B29: עסקאות בתשלומים | D29: =IF(C29="","",C29/3) | E29: =IF(OR(D29="",D$12=0),"",D29/D$12)
B30: הוצאות שנתיות (חלוקה חודשית) | D30: =IF(C30="","",C30/3) | E30: =IF(OR(D30="",D$12=0),"",D30/D$12) | J30: סה"כ ביטוחים | K30: =SUM(K22:K29)
D31: =IF(C31="","",C31/3) | E31: =IF(OR(D31="",D$12=0),"",D31/D$12)
D32: =IF(C32="","",C32/3) | E32: =IF(OR(D32="",D$12=0),"",D32/D$12) | J32: הוצאות שנתיות (מתחלק ל-12)
D33: =IF(C33="","",C33/3) | E33: =IF(OR(D33="",D$12=0),"",D33/D$12) | J33: שם | K33: סכום שנתי | L33: לחודש
B34: סה"כ קבועות | C34: =SUM(C16:C33) | D34: =SUM(D16:D33) | E34: =IF(D$12=0,"",D34/D$12) | J34: אגרה שנתית + טסט — רכב 1 | L34: =IFERROR(K34/12,0)
J35: אגרה שנתית + טסט — רכב 2 | L35: =IFERROR(K35/12,0)
B36: הוצאות משתנות | J36: ביטוח וטיפולי רכב | L36: =IFERROR(K36/12,0)
B37: קטגוריה | C37: סה"כ 3 חודשים | D37: ממוצע לחודש | E37: % מהכנסה | J37: נופש משפחתי | L37: =IFERROR(K37/12,0)
B38: מזון לבית (סופר) | D38: =IF(C38="","",C38/3) | E38: =IF(OR(D38="",D$12=0),"",D38/D$12) | J38: מתנות וחגים | L38: =IFERROR(K38/12,0)
B39: אוכל בחוץ ובילויים | D39: =IF(C39="","",C39/3) | E39: =IF(OR(D39="",D$12=0),"",D39/D$12) | L39: =IFERROR(K39/12,0)
B40: תחבורה (דלק, חניה, תחב"צ) | D40: =IF(C40="","",C40/3) | E40: =IF(OR(D40="",D$12=0),"",D40/D$12) | J40: סה"כ לחודש | L40: =SUM(L34:L39)
...

Sheet חובות
B1: חובות ותשלומים | I1: 🏠 בית
B2: פעם אחת כאן — וזה זורם לתזרים לבד.
B4: הלוואות | I4: מחשבון איחוד הלוואות
B5: שם ההלוואה / הבנק | C5: יתרת קרן | D5: ריבית שנתית | E5: החזר חודשי | F5: חודשים שנותרו | I5: יתרת חוב לאיחוד | J5: =C16
I6: החזר חודשי נוכחי | J6: =E16
I7: ריבית שנתית חדשה | J7: 0.08
I8: תקופה חדשה (חודשים) | J8: 60
I9: החזר חודשי חדש | J9: =IFERROR(-PMT(J7/12,J8,J5),0)
I10: שינוי בהחזר (+ = חיסכון) | J10: =IFERROR(J6-J9,0)
I11: סה"כ שישולם | J11: =IFERROR(J9*J8,0)
I12: מזה ריבית | J12: =IFERROR(J11-J5,0)
I14: החזר נמוך יותר ≠ זול יותר: תקופה ארוכה מגדילה את הריבית. להסתכל על שתי השורות האחרונות.
B16: סה"כ | C16: =SUM(C6:C15) | E16: =SUM(E6:E15)
B18: עסקאות בתשלומים (מדפי האשראי)
B19: שם העסק | C19: תאריך העסקה | D19: מס' תשלומים | E19: סכום חודשי | F19: בוצעו | G19: נותרו
F20: =IF(OR(K20=0,D20=""),0,MIN(D20,MAX(0,(YEAR(TODAY())-YEAR(K20))*12+MONTH(TODAY())-MONTH(K20)+1))) | G20: =IF(D20="",0,MAX(0,D20-F20)) | K20: =IF(ISNUMBER(C20),C20,IFERROR(DATEVALUE(SUBSTITUTE(SUBSTITUTE(TRIM(C20),".","/"),"-","/")),0))
F21: =IF(OR(K21=0,D21=""),0,MIN(D21,MAX(0,(YEAR(TODAY())-YEAR(K21))*12+MONTH(TODAY())-MONTH(K21)+1))) | G21: =IF(D21="",0,MAX(0,D21-F21)) | K21: =IF(ISNUMBER(C21),C21,IFERROR(DATEVALUE(SUBSTITUTE(SUBSTITUTE(TRIM(C21),".","/"),"-","/")),0))
F22: =IF(OR(K22=0,D22=""),0,MIN(D22,MAX(0,(YEAR(TODAY())-YEAR(K22))*12+MONTH(TODAY())-MONTH(K22)+1))) | G22: =IF(D22="",0,MAX(0,D22-F22)) | K22: =IF(ISNUMBER(C22),C22,IFERROR(DATEVALUE(SUBSTITUTE(SUBSTITUTE(TRIM(C22),".","/"),"-","/")),0))
F23: =IF(OR(K23=0,D23=""),0,MIN(D23,MAX(0,(YEAR(TODAY())-YEAR(K23))*12+MONTH(TODAY())-MONTH(K23)+1))) | G23: =IF(D23="",0,MAX(0,D23-F23)) | K23: =IF(ISNUMBER(C23),C23,IFERROR(DATEVALUE(SUBSTITUTE(SUBSTITUTE(TRIM(C23),".","/"),"-","/")),0))
F24: =IF(OR(K24=0,D24=""),0,MIN(D24,MAX(0,(YEAR(TODAY())-YEAR(K24))*12+MONTH(TODAY())-MONTH(K24)+1))) | G24: =IF(D24="",0,MAX(0,D24-F24)) | K24: =IF(ISNUMBER(C24),C24,IFERROR(DATEVALUE(SUBSTITUTE(SUBSTITUTE(TRIM(C24),".","/"),"-","/")),0))
F25: =IF(OR(K25=0,D25=""),0,MIN(D25,MAX(0,(YEAR(TODAY())-YEAR(K25))*12+MONTH(TODAY())-MONTH(K25)+1))) | G25: =IF(D25="",0,MAX(0,D25-F25)) | K25: =IF(ISNUMBER(C25),C25,IFERROR(DATEVALUE(SUBSTITUTE(SUBSTITUTE(TRIM(C25),".","/"),"-","/")),0))
F26: =IF(OR(K26=0,D26=""),0,MIN(D26,MAX(0,(YEAR(TODAY())-YEAR(K26))*12+MONTH(TODAY())-MONTH(K26)+1))) | G26: =IF(D26="",0,MAX(0,D26-F26)) | K26: =IF(ISNUMBER(C26),C26,IFERROR(DATEVALUE(SUBSTITUTE(SUBSTITUTE(TRIM(C26),".","/"),"-","/")),0))
F27: =IF(OR(K27=0,D27=""),0,MIN(D27,MAX(0,(YEAR(TODAY())-YEAR(K27))*12+MONTH(TODAY())-MONTH(K27)+1))) | G27: =IF(D27="",0,MAX(0,D27-F27)) | K27: =IF(ISNUMBER(C27),C27,IFERROR(DATEVALUE(SUBSTITUTE(SUBSTITUTE(TRIM(C27),".","/"),"-","/")),0))
F28: =IF(OR(K28=0,D28=""),0,MIN(D28,MAX(0,(YEAR(TODAY())-YEAR(K28))*12+MONTH(TODAY())-MONTH(K28)+1))) | G28: =IF(D28="",0,MAX(0,D28-F28)) | K28: =IF(ISNUMBER(C28),C28,IFERROR(DATEVALUE(SUBSTITUTE(SUBSTITUTE(TRIM(C28),".","/"),"-","/")),0))
F29: =IF(OR(K29=0,D29=""),0,MIN(D29,MAX(0,(YEAR(TODAY())-YEAR(K29))*12+MONTH(TODAY())-MONTH(K29)+1))) | G29: =IF(D29="",0,MAX(0,D29-F29)) | K29: =IF(ISNUMBER(C29),C29,IFERROR(DATEVALUE(SUBSTITUTE(SUBSTITUTE(TRIM(C29),".","/"),"-","/")),0))
F30: =IF(OR(K30=0,D30=""),0,MIN(D30,MAX(0,(YEAR(TODAY())-YEAR(K30))*12+MONTH(TODAY())-MONTH(K30)+1))) | G30: =IF(D30="",0,MAX(0,D30-F30)) | K30: =IF(ISNUMBER(C30),C30,IFERROR(DATEVALUE(SUBSTITUTE(SUBSTITUTE(TRIM(C30),".","/"),"-","/")),0))
F31: =IF(OR(K31=0,D31=""),0,MIN(D31,MAX(0,(YEAR(TODAY())-YEAR(K31))*12+MONTH(TODAY())-MONTH(K31)+1))) | G31: =IF(D31="",0,MAX(0,D31-F31)) | K31: =IF(ISNUMBER(C31),C31,IFERROR(DATEVALUE(SUBSTITUTE(SUBSTITUTE(TRIM(C31),".","/"),"-","/")),0))
... F33: =IF(OR(K33=0,D33=""),0,MIN(D33,MAX(0,(YEAR(TODAY())-YEAR(K33))*12+MONTH(TODAY())-MONTH(K33)+1))) | G33: =IF(D33="",0,MAX(0,D33-F33)) | K33: =IF(ISNUMBER(C33),C33,IFERROR(DATEVALUE(SUBSTITUTE(SUBSTITUTE(TRIM(C33),".","/"),"-","/")),0))
B34: סה"כ פעיל בתשלום | E34: =SUMPRODUCT((G20:G33>0)*(E20:E33))
B35: תאריך אפשר בכל צורה: 15/3/2026 או 15.3.2026. העסקה נופלת מהתזרים לבד כשהיא נגמרת.
B37: משכנתא — שווי הנכס ואחוז המימון
B38: שווי הנכס | C38: =IF(N(מאזן!C14)>0,מאזן!C14,"") | D38: ← נמשך מהמאזן (אפשר לדרוס)
B39: יתרת המשכנתא
B40: החזר חודשי
B41: ריבית ממוצעת
B42: שנים שנותרו
B44: ◄ LTV — אחוז המימון | C44: =IFERROR(N(C39)/C38,"")
B45: ◄ ההון שלכם בנכס | C45: =IF(N(C38)=0,"",C38-N(C39))
B47: תקרת מימון | C47: 0.5
B48: ◄ ניתן להשלים עוד עד התקרה | C48: =IF(N(C38)=0,"",MAX(0,C38*N(C47)-N(C39)))
...

Sheet מאזן
B1: מאזן וחשבונות | I1: 🏠 בית
B2: מה יש, מה חייבים, הכלים בבנק — והשווי הנקי. מעדכנים פעם בחצי שנה.
B4: מה יש לנו — נכסים | H4: יחסי חוב — מבט מהיר
B5: נכס | C5: שווי נוכחי | H5: מדד | I5: הערך | J5: יעד | K5: סטטוס
B6: עו"ש ופיקדונות | C6: =IF(COUNT(C69:H69)>0,LOOKUP(2,1/(C69:H69<>""),C69:H69),IF(SUM(K12:K17)=0,"",SUM(K12:K17))) | H6: LTV — משכנתא מול הדירה | I6: =IFERROR(C21/C14,0) | J6: ≤ 70% | K6: =IF(I6<=0.7,"🟢",IF(I6<=0.8,"🟡","🔴"))
B7: קרן כספית / חיסכון נזיל | C7: =IFERROR(LOOKUP(2,1/(C70:H70<>""),C70:H70),"") | H7: חוב מול הכנסה שנתית | I7: =IFERROR(C25/MAX(1,IF(תזרים!$AC$2>0,תזרים!AB12/תזרים!$AC$2*12,תזרים!AA12)),0) | J7: ≤ פי 4 | K7: =IF(I7<=4,"🟢",IF(I7<=5,"🟡","🔴"))
B8: קרן השתלמות | C8: =IF(COUNT(C71:H71)>0,LOOKUP(2,1/(C71:H71<>""),C71:H71),IF(K60=0,"",K60)) | H8: מינוף — חוב מול נכסים | I8: =IFERROR(C25/C17,0) | J8: ≤ 50% | K8: =IF(I8<=0.5,"🟢",IF(I8<=0.7,"🟡","🔴"))
B9: גמל להשקעה | C9: =IF(COUNT(C72:H72)>0,LOOKUP(2,1/(C72:H72<>""),C72:H72),IF(K61=0,"",K61))
B10: תיק השקעות | C10: =IF(COUNT(C73:H73)>0,LOOKUP(2,1/(C73:H73<>""),C73:H73),IF(K62=0,"",K62)) | H10: חשבונות בנק — הכלים של הזוג
B11: חיסכון לילדים | C11: =IFERROR(LOOKUP(2,1/(C74:H74<>""),C74:H74),"") | H11: בנק / סניף | I11: מספר חשבון | J11: בעלים | K11: יתרה | L11: מסגרת
B12: ="פנסיה — "&IF(שאלון!$C$6="","בן/בת זוג 1",שאלון!$C$6) | C12: =IFERROR(LOOKUP(2,1/(C75:H75<>""),C75:H75),"")
B13: ="פנסיה — "&IF(שאלון!$D$6="","בן/בת זוג 2",שאלון!$D$6) | C13: =IFERROR(LOOKUP(2,1/(C76:H76<>""),C76:H76),"")
B14: דירה (שווי שוק) | C14: =IFERROR(LOOKUP(2,1/(C77:H77<>""),C77:H77),"")
B15: רכב | C15: =IFERROR(LOOKUP(2,1/(C78:H78<>""),C78:H78),"")
B16: אחר | C16: =IFERROR(LOOKUP(2,1/(C79:H79<>""),C79:H79),"")
B17: סה"כ נכסים | C17: =SUM(C6:C16)
H18: סה"כ | K18: =SUM(K12:K17) | L18: =SUM(L12:L17)
B19: מה אנחנו חייבים — התחייבויות
B20: התחייבות | C20: יתרה | H20: כרטיסי אשראי
B21: משכנתא | C21: =IFERROR(חובות!C39,0) | D21: נמשך מדף חובות | H21: כרטיס / חברה | I21: 4 ספרות | J21: משויך לחשבון | K21: יום חיוב | L21: מסגרת
B22: הלוואות (נמשך מדף חובות) | C22: =חובות!C16
B23: מסגרות אשראי מנוצלות
B24: אחר
B25: סה"כ התחייבויות | C25: =SUM(C21:C24)
B27: השווי הנקי של המשפחה
B28: =C17-C25 | H28: סה"כ מסגרות | L28: =SUM(L22:L27)
B30: שווי נקי = נכסים פחות התחייבויות. זה המספר שעוקבים אחריו שנה אחרי שנה — לא היתרה בעו"ש.
B32: פנסיוני — מבט קדימה
C33: =IF(שאלון!C6="","בן/בת זוג 1",שאלון!C6) | D33: =IF(שאלון!D6="","בן/בת זוג 2",שאלון!D6)
B34: גיל נוכחי (מהשאלון) | C34: =N(שאלון!C7) | D34: =N(שאלון!D7)
B35: גיל פרישה | C35: 67 | D35: 67
B36: צבירה נוכחית (מהנכסים למעלה) | C36: =N(C12) | D36: =N(C13)
B37: הפקדה חודשית לפנסיה
B38: דמי ניהול מצבירה | C38: 0.005 | D38: 0.005
B39: דמי ניהול מהפקדה | C39: 0.02 | D39: 0.02
B40: תשואה שנתית להנחה | C40: 0.04 | D40: 0.04
B41: ◄ צפי צבירה בפרישה | C41: =IFERROR(FV(C40-C38,MAX(0,C35-C34),-C37*12*(1-C39),-C36),0) | D41: =IFERROR(FV(D40-D38,MAX(0,D35-D34),-D37*12*(1-D39),-D36),0)
B42: מקדם המרה | C42: 200 | D42: 200
B43: ◄ קצבה חודשית צפויה | C43: =IFERROR(C41/C42,0) | D43: =IFERROR(D41/D42,0)
B44: קצבה משפחתית + שיעור תחלופה | C44: =C43+D43 | D44: =IFERROR((C43+D43)/MAX(1,IF(תזרים!$AC$2>0,תזרים!AB12/תזרים!$AC$2,תזרים!AA12/12)),0)
...

Sheet מטרות ויעדים
B1: מטרות ויעדים — לתת צבע לכסף | I1: 🏠 בית
B2: כל מטרה: כמה תעלה באמת, כמה צריך היום, וכמה מפקידים כל חודש.
B3: שנת הבסיס: | C3: =YEAR(תזרים!C62) | D3: אינפלציה שנתית: | E3: 0.02 | F3: עלות עתידית = היום × אינפלציה. תשואה נטו = ברוטו − אינפלציה − דמי ניהול.
B4: מטרה | C4: שנת יעד | D4: שנים | E4: עלות היום | F4: עלות עתידית | G4: תשואה ברוטו | H4: דמי ניהול | I4: תשואה נטו | J4: צריך היום — חד-פעמי | K4: יש כבר ₪ | L4: ◄ חסר | M4: להפקיד כל חודש | N4: מקצים בפועל ₪ | O4: פער | P4: הערות
B5: =IF(שאלון!B50="","",שאלון!B50) | C5: =IF(שאלון!C50="","",שאלון!C50) | D5: =IF(C5="","",MAX(1,C5-$C$3)) | E5: =IF(שאלון!D50="","",שאלון!D50) | F5: =IF(OR(E5="",D5=""),"",E5*(1+$E$3)^D5) | H5: 0.007 | I5: =IF(G5="","",G5-$E$3-H5) | J5: =IF(OR(F5="",I5=""),"",F5/(1+I5)^D5) | L5: =IF(J5="","",MAX(0,J5-N(K5))) | M5: =IF(F5="","",IF(I5="","",MAX(0,IFERROR(-PMT(I5/12,D5*12,-N(K5),F5),IFERROR((F5-N(K5))/(D5*12),0))))) | O5: =IF(OR(M5="",M5=0),"",IF(N(N5)>=M5,"✔",M5-N(N5)))
B6: =IF(שאלון!B51="","",שאלון!B51) | C6: =IF(שאלון!C51="","",שאלון!C51) | D6: =IF(C6="","",MAX(1,C6-$C$3)) | E6: =IF(שאלון!D51="","",שאלון!D51) | F6: =IF(OR(E6="",D6=""),"",E6*(1+$E$3)^D6) | H6: 0.007 | I6: =IF(G6="","",G6-$E$3-H6) | J6: =IF(OR(F6="",I6=""),"",F6/(1+I6)^D6) | L6: =IF(J6="","",MAX(0,J6-N(K6))) | M6: =IF(F6="","",IF(I6="","",MAX(0,IFERROR(-PMT(I6/12,D6*12,-N(K6),F6),IFERROR((F6-N(K6))/(D6*12),0))))) | O6: =IF(OR(M6="",M6=0),"",IF(N(N6)>=M6,"✔",M6-N(N6)))
B7: =IF(שאלון!B52="","",שאלון!B52) | C7: =IF(שאלון!C52="","",שאלון!C52) | D7: =IF(C7="","",MAX(1,C7-$C$3)) | E7: =IF(שאלון!D52="","",שאלון!D52) | F7: =IF(OR(E7="",D7=""),"",E7*(1+$E$3)^D7) | H7: 0.007 | I7: =IF(G7="","",G7-$E$3-H7) | J7: =IF(OR(F7="",I7=""),"",F7/(1+I7)^D7) | L7: =IF(J7="","",MAX(0,J7-N(K7))) | M7: =IF(F7="","",IF(I7="","",MAX(0,IFERROR(-PMT(I7/12,D7*12,-N(K7),F7),IFERROR((F7-N(K7))/(D7*12),0))))) | O7: =IF(OR(M7="",M7=0),"",IF(N(N7)>=M7,"✔",M7-N(N7)))
B8: =IF(שאלון!B53="","",שאלון!B53) | C8: =IF(שאלון!C53="","",שאלון!C53) | D8: =IF(C8="","",MAX(1,C8-$C$3)) | E8: =IF(שאלון!D53="","",שאלון!D53) | F8: =IF(OR(E8="",D8=""),"",E8*(1+$E$3)^D8) | H8: 0.007 | I8: =IF(G8="","",G8-$E$3-H8) | J8: =IF(OR(F8="",I8=""),"",F8/(1+I8)^D8) | L8: =IF(J8="","",MAX(0,J8-N(K8))) | M8: =IF(F8="","",IF(I8="","",MAX(0,IFERROR(-PMT(I8/12,D8*12,-N(K8),F8),IFERROR((F8-N(K8))/(D8*12),0))))) | O8: =IF(OR(M8="",M8=0),"",IF(N(N8)>=M8,"✔",M8-N(N8)))
B9: =IF(שאלון!B54="","",שאלון!B54) | C9: =IF(שאלון!C54="","",שאלון!C54) | D9: =IF(C9="","",MAX(1,C9-$C$3)) | E9: =IF(שאלון!D54="","",שאלון!D54) | F9: =IF(OR(E9="",D9=""),"",E9*(1+$E$3)^D9) | H9: 0.007 | I9: =IF(G9="","",G9-$E$3-H9) | J9: =IF(OR(F9="",I9=""),"",F9/(1+I9)^D9) | L9: =IF(J9="","",MAX(0,J9-N(K9))) | M9: =IF(F9="","",IF(I9="","",MAX(0,IFERROR(-PMT(I9/12,D9*12,-N(K9),F9),IFERROR((F9-N(K9))/(D9*12),0))))) | O9: =IF(OR(M9="",M9=0),"",IF(N(N9)>=M9,"✔",M9-N(N9)))
B10: =IF(שאלון!B55="","",שאלון!B55) | C10: =IF(שאלון!C55="","",שאלון!C55) | D10: =IF(C10="","",MAX(1,C10-$C$3)) | E10: =IF(שאלון!D55="","",שאלון!D55) | F10: =IF(OR(E10="",D10=""),"",E10*(1+$E$3)^D10) | H10: 0.007 | I10: =IF(G10="","",G10-$E$3-H10) | J10: =IF(OR(F10="",I10=""),"",F10/(1+I10)^D10) | L10: =IF(J10="","",MAX(0,J10-N(K10))) | M10: =IF(F10="","",IF(I10="","",MAX(0,IFERROR(-PMT(I10/12,D10*12,-N(K10),F10),IFERROR((F10-N(K10))/(D10*12),0))))) | O10: =IF(OR(M10="",M10=0),"",IF(N(N10)>=M10,"✔",M10-N(N10)))
B11: =IF(שאלון!B56="","",שאלון!B56) | C11: =IF(שאלון!C56="","",שאלון!C56) | D11: =IF(C11="","",MAX(1,C11-$C$3)) | E11: =IF(שאלון!D56="","",שאלון!D56) | F11: =IF(OR(E11="",D11=""),"",E11*(1+$E$3)^D11) | H11: 0.007 | I11: =IF(G11="","",G11-$E$3-H11) | J11: =IF(OR(F11="",I11=""),"",F11/(1+I11)^D11) | L11: =IF(J11="","",MAX(0,J11-N(K11))) | M11: =IF(F11="","",IF(I11="","",MAX(0,IFERROR(-PMT(I11/12,D11*12,-N(K11),F11),IFERROR((F11-N(K11))/(D11*12),0))))) | O11: =IF(OR(M11="",M11=0),"",IF(N(N11)>=M11,"✔",M11-N(N11)))
B12: =IF(שאלון!B57="","",שאלון!B57) | C12: =IF(שאלון!C57="","",שאלון!C57) | D12: =IF(C12="","",MAX(1,C12-$C$3)) | E12: =IF(שאלון!D57="","",שאלון!D57) | F12: =IF(OR(E12="",D12=""),"",E12*(1+$E$3)^D12) | H12: 0.007 | I12: =IF(G12="","",G12-$E$3-H12) | J12: =IF(OR(F12="",I12=""),"",F12/(1+I12)^D12) | L12: =IF(J12="","",MAX(0,J12-N(K12))) | M12: =IF(F12="","",IF(I12="","",MAX(0,IFERROR(-PMT(I12/12,D12*12,-N(K12),F12),IFERROR((F12-N(K12))/(D12*12),0))))) | O12: =IF(OR(M12="",M12=0),"",IF(N(N12)>=M12,"✔",M12-N(N12)))
B13: =IF(שאלון!B58="","",שאלון!B58) | C13: =IF(שאלון!C58="","",שאלון!C58) | D13: =IF(C13="","",MAX(1,C13-$C$3)) | E13: =IF(שאלון!D58="","",שאלון!D58) | F13: =IF(OR(E13="",D13=""),"",E13*(1+$E$3)^D13) | H13: 0.007 | I13: =IF(G13="","",G13-$E$3-H13) | J13: =IF(OR(F13="",I13=""),"",F13/(1+I13)^D13) | L13: =IF(J13="","",MAX(0,J13-N(K13))) | M13: =IF(F13="","",IF(I13="","",MAX(0,IFERROR(-PMT(I13/12,D13*12,-N(K13),F13),IFERROR((F13-N(K13))/(D13*12),0))))) | O13: =IF(OR(M13="",M13=0),"",IF(N(N13)>=M13,"✔",M13-N(N13)))
B14: =IF(שאלון!B59="","",שאלון!B59) | C14: =IF(שאלון!C59="","",שאלון!C59) | D14: =IF(C14="","",MAX(1,C14-$C$3)) | E14: =IF(שאלון!D59="","",שאלון!D59) | F14: =IF(OR(E14="",D14=""),"",E14*(1+$E$3)^D14) | H14: 0.007 | I14: =IF(G14="","",G14-$E$3-H14) | J14: =IF(OR(F14="",I14=""),"",F14/(1+I14)^D14) | L14: =IF(J14="","",MAX(0,J14-N(K14))) | M14: =IF(F14="","",IF(I14="","",MAX(0,IFERROR(-PMT(I14/12,D14*12,-N(K14),F14),IFERROR((F14-N(K14))/(D14*12),0))))) | O14: =IF(OR(M14="",M14=0),"",IF(N(N14)>=M14,"✔",M14-N(N14)))
D15: =IF(C15="","",MAX(1,C15-$C$3)) | F15: =IF(OR(E15="",D15=""),"",E15*(1+$E$3)^D15) | H15: 0.007 | I15: =IF(G15="","",G15-$E$3-H15) | J15: =IF(OR(F15="",I15=""),"",F15/(1+I15)^D15) | L15: =IF(J15="","",MAX(0,J15-N(K15))) | M15: =IF(F15="","",IF(I15="","",MAX(0,IFERROR(-PMT(I15/12,D15*12,-N(K15),F15),IFERROR((F15-N(K15))/(D15*12),0))))) | O15: =IF(OR(M15="",M15=0),"",IF(N(N15)>=M15,"✔",M15-N(N15)))
D16: =IF(C16="","",MAX(1,C16-$C$3)) | F16: =IF(OR(E16="",D16=""),"",E16*(1+$E$3)^D16) | H16: 0.007 | I16: =IF(G16="","",G16-$E$3-H16) | J16: =IF(OR(F16="",I16=""),"",F16/(1+I16)^D16) | L16: =IF(J16="","",MAX(0,J16-N(K16))) | M16: =IF(F16="","",IF(I16="","",MAX(0,IFERROR(-PMT(I16/12,D16*12,-N(K16),F16),IFERROR((F16-N(K16))/(D16*12),0))))) | O16: =IF(OR(M16="",M16=0),"",IF(N(N16)>=M16,"✔",M16-N(N16)))
B17: סה"כ | E17: =SUM(E5:E16) | F17: =SUM(F5:F16) | J17: =SUM(J5:J16) | K17: =SUM(K5:K16) | L17: =SUM(L5:L16) | M17: =SUM(M5:M16) | N17: =SUM(N5:N16)
B19: ① הפער ההוני — כמה כסף צריך שיהיה מושקע היום
B20: צריך היום (מהוון) | C20: =J17 | E20: מזה כבר משויך | F20: =K17 | H20: ◄ פער הוני | I20: =MAX(0,J17-K17) | K20: =IF(J17=0,"",IF(I20=0,"🟢 כל ההון למטרות כבר מושקע","עוד "&TEXT(I20,"#,##0")&" ₪ חסרים כהון — או שנשלים אותם בהפקדה חודשית"))
B21: ② הפער התזרימי — כמה צריך להפקיד כל חודש
B22: צריך להפקיד בחודש | C22: =M17 | E22: מקצים בפועל | F22: =N17 | H22: ◄ פער תזרימי | I22: =MAX(0,M17-N17) | K22: =IF(M17=0,"",IF(I22=0,"🟢 כל המטרות מקבלות את ההפקדה שהן צריכות","חסרים "&TEXT(I22,"#,##0")&" ₪ בחודש כדי לכסות את כל המטרות"))
B23: ③ הארנק — התזרים הפנוי שיש לחלק
B24: תזרים פנוי (מהמיפוי) | C24: =IFERROR(N(מיפוי!D59),0) | E24: מזה חולק למטרות | F24: =N17 | H24: ◄ נשאר לחלוקה | I24: =C24-N17 | K24: =IF(C24=0,"מלאו את המיפוי — משם מגיע התזרים הפנוי",IF(I24<0,"🔴 חילקתם "&TEXT(-I24,"#,##0")&" ₪ יותר ממה שיש בתזרים",IF(I24>50,"⚠️ נשארו "&TEXT(I24,"#,##0")&" ₪ בלי יעד — כסף שלא מוקצה מתאדה","🟢 כל שקל מהתזרים הפנוי קיבל יעד")))
B26: =IF(M17=0,"מלאו מטרות בשאלון — עלות, שנת יעד ותשואה צפויה",IF(AND(I20=0,I22=0),"🟢 התכנית סגורה: ההון והתזרים מכסים את כל המטרות",IF(C24+50<C22,"🔴 גם אם תחלקו את כל התזרים הפנוי ("&TEXT(C24,"#,##0")&" ₪) עדיין חסרים "&TEXT(C22-C24,"#,##0")&" ₪ בחודש — צריך לשחרר תזרים, לשייך הון או לדחות יעד",IF(I22>0,"⚠️ יש מספיק תזרים — צריך רק להקצות אותו: חסרים עוד "&TEXT(I22,"#,##0")&" ₪ בעמודת 'מקצים בפועל'","🟢 כל המטרות מכוסות"))))
B28: "יש כבר" = כסף חד-פעמי שמשייכים למטרה (חיסכון, קרן השתלמות). ככל שיש יותר — "להפקיד כל חודש" קטן. תשואה לפי טווח: עד 3 שנים 0-2% · 3-7 שנים 4-5% · מעל 7 שנים 6-7%.

Sheet תזרים
B1: תזרים — תכנון מול ביצוע | AB1: =IF(C2="ינואר",1,IF(C2="פברואר",2,IF(C2="מרץ",3,IF(C2="אפריל",4,IF(C2="מאי",5,IF(C2="יוני",6,IF(C2="יולי",7,IF(C2="אוגוסט",8,IF(C2="ספטמבר",9,IF(C2="אוקטובר",10,IF(C2="נובמבר",11,IF(C2="דצמבר",12,1)))))))))))) | AC1: 🏠 בית
B2: תחילת פעילות — חודש: | D2: שנה: | F2: שנת פעילות: | H2: 1 | J2: בוחרים חודש ושנה מהרשימה — וכל התזרים מתיישר. שנה הבאה? מעלים "שנת פעילות" ל-2. | AC2: =SUMPRODUCT((MOD(COLUMN($C$12:$Z$12)-COLUMN($C$12),2)=1)*($C$12:$Z$12>0))
B3: הכנסות
C4: =CHOOSE(MONTH(C62),"ינואר","פברואר","מרץ","אפריל","מאי","יוני","יולי","אוגוסט","ספטמבר","אוקטובר","נובמבר","דצמבר")&" "&YEAR(C62) | E4: =CHOOSE(MONTH(E62),"ינואר","פברואר","מרץ","אפריל","מאי","יוני","יולי","אוגוסט","ספטמבר","אוקטובר","נובמבר","דצמבר")&" "&YEAR(E62) | G4: =CHOOSE(MONTH(G62),"ינואר","פברואר","מרץ","אפריל","מאי","יוני","יולי","אוגוסט","ספטמבר","אוקטובר","נובמבר","דצמבר")&" "&YEAR(G62) | I4: =CHOOSE(MONTH(I62),"ינואר","פברואר","מרץ","אפריל","מאי","יוני","יולי","אוגוסט","ספטמבר","אוקטובר","נובמבר","דצמבר")&" "&YEAR(I62) | K4: =CHOOSE(MONTH(K62),"ינואר","פברואר","מרץ","אפריל","מאי","יוני","יולי","אוגוסט","ספטמבר","אוקטובר","נובמבר","דצמבר")&" "&YEAR(K62) | M4: =CHOOSE(MONTH(M62),"ינואר","פברואר","מרץ","אפריל","מאי","יוני","יולי","אוגוסט","ספטמבר","אוקטובר","נובמבר","דצמבר")&" "&YEAR(M62) | O4: =CHOOSE(MONTH(O62),"ינואר","פברואר","מרץ","אפריל","מאי","יוני","יולי","אוגוסט","ספטמבר","אוקטובר","נובמבר","דצמבר")&" "&YEAR(O62) | Q4: =CHOOSE(MONTH(Q62),"ינואר","פברואר","מרץ","אפריל","מאי","יוני","יולי","אוגוסט","ספטמבר","אוקטובר","נובמבר","דצמבר")&" "&YEAR(Q62) | S4: =CHOOSE(MONTH(S62),"ינואר","פברואר","מרץ","אפריל","מאי","יוני","יולי","אוגוסט","ספטמבר","אוקטובר","נובמבר","דצמבר")&" "&YEAR(S62) | U4: =CHOOSE(MONTH(U62),"ינואר","פברואר","מרץ","אפריל","מאי","יוני","יולי","אוגוסט","ספטמבר","אוקטובר","נובמבר","דצמבר")&" "&YEAR(U62) | W4: =CHOOSE(MONTH(W62),"ינואר","פברואר","מרץ","אפריל","מאי","יוני","יולי","אוגוסט","ספטמבר","אוקטובר","נובמבר","דצמבר")&" "&YEAR(W62) | Y4: =CHOOSE(MONTH(Y62),"ינואר","פברואר","מרץ","אפריל","מאי","יוני","יולי","אוגוסט","ספטמבר","אוקטובר","נובמבר","דצמבר")&" "&YEAR(Y62)
B5: קטגוריה | C5: תכנון | D5: ביצוע | E5: תכנון | F5: ביצוע | G5: תכנון | H5: ביצוע | I5: תכנון | J5: ביצוע | K5: תכנון | L5: ביצוע | M5: תכנון | N5: ביצוע | O5: תכנון | P5: ביצוע | Q5: תכנון | R5: ביצוע | S5: תכנון | T5: ביצוע | U5: תכנון | V5: ביצוע | W5: תכנון | X5: ביצוע | Y5: תכנון | Z5: ביצוע | AA5: סה"כ תכנון | AB5: סה"כ ביצוע
B6: =IF(מיפוי!B6="","",מיפוי!B6) | C6: =IF(מיפוי!D6="","",מיפוי!D6) | E6: =C6 | G6: =E6 | I6: =G6 | K6: =I6 | M6: =K6 | O6: =M6 | Q6: =O6 | S6: =Q6 | U6: =S6 | W6: =U6 | Y6: =W6 | AA6: =SUM(C6,E6,G6,I6,K6,M6,O6,Q6,S6,U6,W6,Y6) | AB6: =SUM(D6,F6,H6,J6,L6,N6,P6,R6,T6,V6,X6,Z6)
B7: =IF(מיפוי!B7="","",מיפוי!B7) | C7: =IF(מיפוי!D7="","",מיפוי!D7) | E7: =C7 | G7: =E7 | I7: =G7 | K7: =I7 | M7: =K7 | O7: =M7 | Q7: =O7 | S7: =Q7 | U7: =S7 | W7: =U7 | Y7: =W7 | AA7: =SUM(C7,E7,G7,I7,K7,M7,O7,Q7,S7,U7,W7,Y7) | AB7: =SUM(D7,F7,H7,J7,L7,N7,P7,R7,T7,V7,X7,Z7)
B8: =IF(מיפוי!B8="","",מיפוי!B8) | C8: =IF(מיפוי!D8="","",מיפוי!D8) | E8: =C8 | G8: =E8 | I8: =G8 | K8: =I8 | M8: =K8 | O8: =M8 | Q8: =O8 | S8: =Q8 | U8: =S8 | W8: =U8 | Y8: =W8 | AA8: =SUM(C8,E8,G8,I8,K8,M8,O8,Q8,S8,U8,W8,Y8) | AB8: =SUM(D8,F8,H8,J8,L8,N8,P8,R8,T8,V8,X8,Z8)
B9: =IF(מיפוי!B9="","",מיפוי!B9) | C9: =IF(עסק!C$10=0,IF(מיפוי!D9="","",מיפוי!D9),עסק!C$10) | E9: =IF(עסק!D$10=0,C9,עסק!D$10) | G9: =IF(עסק!E$10=0,E9,עסק!E$10) | I9: =IF(עסק!F$10=0,G9,עסק!F$10) | K9: =IF(עסק!G$10=0,I9,עסק!G$10) | M9: =IF(עסק!H$10=0,K9,עסק!H$10) | O9: =IF(עסק!I$10=0,M9,עסק!I$10) | Q9: =IF(עסק!J$10=0,O9,עסק!J$10) | S9: =IF(עסק!K$10=0,Q9,עסק!K$10) | U9: =IF(עסק!L$10=0,S9,עסק!L$10) | W9: =IF(עסק!M$10=0,U9,עסק!M$10) | Y9: =IF(עסק!N$10=0,W9,עסק!N$10) | AA9: =SUM(C9,E9,G9,I9,K9,M9,O9,Q9,S9,U9,W9,Y9) | AB9: =SUM(D9,F9,H9,J9,L9,N9,P9,R9,T9,V9,X9,Z9)
B10: =IF(מיפוי!B10="","",מיפוי!B10) | C10: =IF(מיפוי!D10="","",מיפוי!D10) | E10: =C10 | G10: =E10 | I10: =G10 | K10: =I10 | M10: =K10 | O10: =M10 | Q10: =O10 | S10: =Q10 | U10: =S10 | W10: =U10 | Y10: =W10 | AA10: =SUM(C10,E10,G10,I10,K10,M10,O10,Q10,S10,U10,W10,Y10) | AB10: =SUM(D10,F10,H10,J10,L10,N10,P10,R10,T10,V10,X10,Z10)
B11: =IF(מיפוי!B11="","",מיפוי!B11) | C11: =IF(מיפוי!D11="","",מיפוי!D11) | E11: =C11 | G11: =E11 | I11: =G11 | K11: =I11 | M11: =K11 | O11: =M11 | Q11: =O11 | S11: =Q11 | U11: =S11 | W11: =U11 | Y11: =W11 | AA11: =SUM(C11,E11,G11,I11,K11,M11,O11,Q11,S11,U11,W11,Y11) | AB11: =SUM(D11,F11,H11,J11,L11,N11,P11,R11,T11,V11,X11,Z11)
B12: סה"כ הכנסות | C12: =SUM(C6:C11) | D12: =SUM(D6:D11) | E12: =SUM(E6:E11) | F12: =SUM(F6:F11) | G12: =SUM(G6:G11) | H12: =SUM(H6:H11) | I12: =SUM(I6:I11) | J12: =SUM(J6:J11) | ... AB12: =SUM(AB6:AB11)
B14: הוצאות קבועות
B15: =IF(מיפוי!B16="","",מיפוי!B16) | C15: =IF(מיפוי!D16="","",מיפוי!D16) | E15: =C15 | G15: =E15 | I15: =G15 | K15: =I15 | M15: =K15 | O15: =M15 | Q15: =O15 | S15: =Q15 | U15: =S15 | W15: =U15 | Y15: =W15 | AA15: =SUM(C15,E15,G15,I15,K15,M15,O15,Q15,S15,U15,W15,Y15) | AB15: =SUM(D15,F15,H15,J15,L15,N15,P15,R15,T15,V15,X15,Z15)
B16: =IF(מיפוי!B17="","",מיפוי!B17) | C16: =IF(מיפוי!D17="","",מיפוי!D17) | E16: =C16 | G16: =E16 | I16: =G16 | K16: =I16 | M16: =K16 | O16: =M16 | Q16: =O16 | S16: =Q16 | U16: =S16 | W16: =U16 | Y16: =W16 | AA16: =SUM(C16,E16,G16,I16,K16,M16,O16,Q16,S16,U16,W16,Y16) | AB16: =SUM(D16,F16,H16,J16,L16,N16,P16,R16,T16,V16,X16,Z16)
B17: =IF(מיפוי!B18="","",מיפוי!B18) | C17: =IF(מיפוי!D18="","",מיפוי!D18) | E17: =C17 | G17: =E17 | I17: =G17 | K17: =I17 | M17: =K17 | O17: =M17 | Q17: =O17 | S17: =Q17 | U17: =S17 | W17: =U17 | Y17: =W17 | AA17: =SUM(C17,E17,G17,I17,K17,M17,O17,Q17,S17,U17,W17,Y17) | AB17: =SUM(D17,F17,H17,J17,L17,N17,P17,R17,T17,V17,X17,Z17)
B18: =IF(מיפוי!B19="","",מיפוי!B19) | C18: =IF(מיפוי!D19="","",מיפוי!D19) | E18: =C18 | G18: =E18 | I18: =G18 | K18: =I18 | M18: =K18 | O18: =M18 | Q18: =O18 | S18: =Q18 | U18: =S18 | W18: =U18 | Y18: =W18 | AA18: =SUM(C18,E18,G18,I18,K18,M18,O18,Q18,S18,U18,W18,Y18) | AB18: =SUM(D18,F18,H18,J18,L18,N18,P18,R18,T18,V18,X18,Z18)
B19: =IF(מיפוי!B20="","",מיפוי!B20) | C19: =IF(מיפוי!D20="","",מיפוי!D20) | E19: =C19 | G19: =E19 | I19: =G19 | K19: =I19 | M19: =K19 | O19: =M19 | Q19: =O19 | S19: =Q19 | U19: =S19 | W19: =U19 | Y19: =W19 | AA19: =SUM(C19,E19,G19,I19,K19,M19,O19,Q19,S19,U19,W19,Y19) | AB19: =SUM(D19,F19,H19,J19,L19,N19,P19,R19,T19,V19,X19,Z19)
B20: =IF(מיפוי!B21="","",מיפוי!B21) | C20: =IF(מיפוי!D21="","",מיפוי!D21) | E20: =C20 | G20: =E20 | I20: =G20 | K20: =I20 | M20: =K20 | O20: =M20 | Q20: =O20 | S20: =Q20 | U20: =S20 | W20: =U20 | Y20: =W20 | AA20: =SUM(C20,E20,G20,I20,K20,M20,O20,Q20,S20,U20,W20,Y20) | AB20: =SUM(D20,F20,H20,J20,L20,N20,P20,R20,T20,V20,X20,Z20)
B21: =IF(מיפוי!B22="","",מיפוי!B22) | C21: =IF(מיפוי!D22="","",מיפוי!D22) | E21: =C21 | G21: =E21 | I21: =G21 | K21: =I21 | M21: =K21 | O21: =M21 | Q21: =O21 | S21: =Q21 | U21: =S21 | W21: =U21 | Y21: =W21 | AA21: =SUM(C21,E21,G21,I21,K21,M21,O21,Q21,S21,U21,W21,Y21) | AB21: =SUM(D21,F21,H21,J21,L21,N21,P21,R21,T21,V21,X21,Z21)
B22: =IF(מיפוי!B23="","",מיפוי!B23) | C22: =מיפוי!K$30 | E22: =C22 | G22: =E22 | I22: =G22 | K22: =I22 | M22: =K22 | O22: =M22 | Q22: =O22 | S22: =Q22 | U22: =S22 | W22: =U22 | Y22: =W22 | AA22: =SUM(C22,E22,G22,I22,K22,M22,O22,Q22,S22,U22,W22,Y22) | AB22: =SUM(D22,F22,H22,J22,L22,N22,P22,R22,T22,V22,X22,Z22)
B23: =IF(מיפוי!B24="","",מיפוי!B24) | C23: =IF(מיפוי!L$17=0,"",מיפוי!L$17) | E23: =C23 | G23: =E23 | I23: =G23 | K23: =I23 | M23: =K23 | O23: =M23 | Q23: =O23 | S23: =Q23 | U23: =S23 | W23: =U23 | Y23: =W23 | AA23: =SUM(C23,E23,G23,I23,K23,M23,O23,Q23,S23,U23,W23,Y23) | AB23: =SUM(D23,F23,H23,J23,L23,N23,P23,R23,T23,V23,X23,Z23)
B24: =IF(מיפוי!B25="","",מיפוי!B25) | C24: =IF(מיפוי!K$54=0,"",מיפוי!K$54) | E24: =C24 | G24: =E24 | I24: =G24 | K24: =I24 | M24: =K24 | O24: =M24 | Q24: =O24 | S24: =Q24 | U24: =S24 | W24: =U24 | Y24: =W24 | AA24: =SUM(C24,E24,G24,I24,K24,M24,O24,Q24,S24,U24,W24,Y24) | AB24: =SUM(D24,F24,H24,J24,L24,N24,P24,R24,T24,V24,X24,Z24)
B25: =IF(מיפוי!B26="","",מיפוי!B26) | C25: =IF(מיפוי!D26="","",מיפוי!D26) | E25: =C25 | G25: =E25 | I25: =G25 | K25: =I25 | M25: =K25 | O25: =M25 | Q25: =O25 | S25: =Q25 | U25: =S25 | W25: =U25 | Y25: =W25 | AA25: =SUM(C25,E25,G25,I25,K25,M25,O25,Q25,S25,U25,W25,Y25) | AB25: =SUM(D25,F25,H25,J25,L25,N25,P25,R25,T25,V25,X25,Z25)
B26: =IF(מיפוי!B27="","",מיפוי!B27) | C26: =IF(מיפוי!D27="","",מיפוי!D27) | E26: =C26 | G26: =E26 | I26: =G26 | K26: =I26 | M26: =K26 | O26: =M26 | Q26: =O26 | S26: =Q26 | U26: =S26 | W26: =U26 | Y26: =W26 | AA26: =SUM(C26,E26,G26,I26,K26,M26,O26,Q26,S26,U26,W26,Y26) | AB26: =SUM(D26,F26,H26,J26,L26,N26,P26,R26,T26,V26,X26,Z26)
B27: =IF(מיפוי!B28="","",מיפוי!B28) | C27: =חובות!E$16 | E27: =C27 | G27: =E27 | I27: =G27 | K27: =I27 | M27: =K27 | O27: =M27 | Q27: =O27 | S27: =Q27 | U27: =S27 | W27: =U27 | Y27: =W27 | AA27: =SUM(C27,E27,G27,I27,K27,M27,O27,Q27,S27,U27,W27,Y27) | AB27: =SUM(D27,F27,H27,J27,L27,N27,P27,R27,T27,V27,X27,Z27)
B28: =IF(מיפוי!B29="","",מיפוי!B29) | C28: =SUMPRODUCT(((YEAR(חובות!$K$20:$K$33)*12+MONTH(חובות!$K$20:$K$33))<=(YEAR(C$62)*12+MONTH(C$62)))*((YEAR(חובות!$K$20:$K$33)*12+MONTH(חובות!$K$20:$K$33)+חובות!$D$20:$D$33-1)>=(YEAR(C$62)*12+MONTH(C$62)))*(חובות!$E$20:$E$33)) | E28: =SUMPRODUCT(((YEAR(חובות!$K$20:$K$33)*12+MONTH(חובות!$K$20:$K$33))<=(YEAR(E$62)*12+MONTH(E$62)))*((YEAR(חובות!$K$20:$K$33)*12+MONTH(חובות!$K$20:$K$33)+חובות!$D$20:$D$33-1)>=(YEAR(E$62)*12+MONTH(E$62)))*(חובות!$E$20:$E$33)) | G28: =SUMPRODUCT(((YEAR(חובות!$K$20:$K$33)*12+MONTH(חובות!$K$20:$K$33))<=(YEAR(G$62)*12+MONTH(G$62)))*((YEAR(חובות!$K$20:$K$33)*12+MONTH(חובות!$K$20:$K$33)+חובות!$D$20:$D$33-1)>=(YEAR(G$62)*12+MONTH(G$62)))*(חובות!$E$20:$E$33)) | I28: =SUMPRODUCT(((YEAR(חובות!$K$20:$K$33)*12+MONTH(חובות!$K$20:$K$33))<=(YEAR(I$62)*12+MONTH(I$62)))*((YEAR(חובות!$K$20:$K$33)*12+MONTH(חובות!$K$20:$K$33)+חובות!$D$20:$D$33-1)>=(YEAR(I$62)*12+MONTH(I$62)))*(חובות!$E$20:$E$33)) | K28: =SUMPRODUCT(((YEAR(חובות!$K$20:$K$33)*12+MONTH(חובות!$K$20:$K$33))<=(YEAR(K$62)*12+MONTH(K$62)))*((YEAR(חובות!$K$20:$K$33)*12+MONTH(חובות!$K$20:$K$33)+חובות!$D$20:$D$33-1)>=(YEAR(K$62)*12+MONTH(K$62)))*(חובות!$E$20:$E$33)) | M28: =SUMPRODUCT(((YEAR(חובות!$K$20:$K$33)*12+MONTH(חובות!$K$20:$K$33))<=(YEAR(M$62)*12+MONTH(M$62)))*((YEAR(חובות!$K$20:$K$33)*12+MONTH(חובות!$K$20:$K$33)+חובות!$D$20:$D$33-1)>=(YEAR(M$62)*12+MONTH(M$62)))*(חובות!$E$20:$E$33)) | O28: =SUMPRODUCT(((YEAR(חובות!$K$20:$K$33)*12+MONTH(חובות!$K$20:$K$33))<=(YEAR(O$62)*12+MONTH(O$62)))*((YEAR(חובות!$K$20:$K$33)*12+MONTH(חובות!$K$20:$K$33)+חובות!$D$20:$D$33-1)>=(YEAR(O$62)*12+MONTH(O$62)))*(חובות!$E$20:$E$33)) | Q28: =SUMPRODUCT(((YEAR(חובות!$K$20:$K$33)*12+MONTH(חובות!$K$20:$K$33))<=(YEAR(Q$62)*12+MONTH(Q$62)))*((YEAR(חובות!$K$20:$K$33)*12+MONTH(חובות!$K$20:$K$33)+חובות!$D$20:$D$33-1)>=(YEAR(Q$62)*12+MONTH(Q$62)))*(חובות!$E$20:$E$33)) | S28: =SUMPRODUCT(((YEAR(חובות!$K$20:$K$33)*12+MONTH(חובות!$K$20:$K$33))<=(YEAR(S$62)*12+MONTH(S$62)))*((YEAR(חובות!$K$20:$K$33)*12+MONTH(חובות!$K$20:$K$33)+חובות!$D$20:$D$33-1)>=(YEAR(S$62)*12+MONTH(S$62)))*(חובות!$E$20:$E$33)) | U28: =SUMPRODUCT(((YEAR(חובות!$K$20:$K$33)*12+MONTH(חובות!$K$20:$K$33))<=(YEAR(U$62)*12+MONTH(U$62)))*((YEAR(חובות!$K$20:$K$33)*12+MONTH(חובות!$K$20:$K$33)+חובות!$D$20:$D$33-1)>=(YEAR(U$62)*12+MONTH(U$62)))*(חובות!$E$20:$E$33)) | W28: =SUMPRODUCT(((YEAR(חובות!$K$20:$K$33)*12+MONTH(חובות!$K$20:$K$33))<=(YEAR(W$62)*12+MONTH(W$62)))*((YEAR(חובות!$K$20:$K$33)*12+MONTH(חובות!$K$20:$K$33)+חובות!$D$20:$D$33-1)>=(YEAR(W$62)*12+MONTH(W$62)))*(חובות!$E$20:$E$33)) | Y28: =SUMPRODUCT(((YEAR(חובות!$K$20:$K$33)*12+MONTH(חובות!$K$20:$K$33))<=(YEAR(Y$62)*12+MONTH(Y$62)))*((YEAR(חובות!$K$20:$K$33)*12+MONTH(חובות!$K$20:$K$33)+חובות!$D$20:$D$33-1)>=(YEAR(Y$62)*12+MONTH(Y$62)))*(חובות!$E$20:$E$33)) | AA28: =SUM(C28,E28,G28,I28,K28,M28,O28,Q28,S28,U28,W28,Y28) | AB28: =SUM(D28,F28,H28,J28,L28,N28,P28,R28,T28,V28,X28,Z28)
B29: =IF(מיפוי!B30="","",מיפוי!B30) | C29: =מיפוי!L$40 | E29: =C29 | G29: =E29 | I29: =G29 | K29: =I29 | M29: =K29 | O29: =M29 | Q29: =O29 | S29: =Q29 | U29: =S29 | W29: =U29 | Y29: =W29 | AA29: =SUM(C29,E29,G29,I29,K29,M29,O29,Q29,S29,U29,W29,Y29) | AB29: =SUM(D29,F29,H29,J29,L29,N29,P29,R29,T29,V29,X29,Z29)
B30: =IF(מיפוי!B31="","",מיפוי!B31) | C30: =IF(מיפוי!D31="","",מיפוי!D31) | E30: =C30 | G30: =E30 | I30: =G30 | K30: =I30 | M30: =K30 | O30: =M30 | Q30: =O30 | S30: =Q30 | U30: =S30 | W30: =U30 | Y30: =W30 | AA30: =SUM(C30,E30,G30,I30,K30,M30,O30,Q30,S30,U30,W30,Y30) | AB30: =SUM(D30,F30,H30,J30,L30,N30,P30,R30,T30,V30,X30,Z30)
B31: =IF(מיפוי!B32="","",מיפוי!B32) | C31: =IF(מיפוי!D32="","",מיפוי!D32) | E31: =C31 | G31: =E31 | I31: =G31 | K31: =I31 | M31: =K31 | O31: =M31 | Q31: =O31 | S31: =Q31 | U31: =S31 | W31: =U31 | Y31: =W31 | AA31: =SUM(C31,E31,G31,I31,K31,M31,O31,Q31,S31,U31,W31,Y31) | AB31: =SUM(D31,F31,H31,J31,L31,N31,P31,R31,T31,V31,X31,Z31)
B32: =IF(מיפוי!B33="","",מיפוי!B33) | C32: =IF(מיפוי!D33="","",מיפוי!D33) | E32: =C32 | G32: =E32 | I32: =G32 | K32: =I32 | M32: =K32 | O32: =M32 | Q32: =O32 | S32: =Q32 | U32: =S32 | W32: =U32 | Y32: =W32 | AA32: =SUM(C32,E32,G32,I32,K32,M32,O32,Q32,S32,U32,W32,Y32) | AB32: =SUM(D32,F32,H32,J32,L32,N32,P32,R32,T32,V32,X32,Z32)
B33: סה"כ קבועות | C33: =SUM(C15:C32) | D33: =SUM(D15:D32) | E33: =SUM(E15:E32) | F33: =SUM(F15:F32) | G33: =SUM(G15:G32) | H33: =SUM(H15:H32) | I33: =SUM(I15:I32) | J33: =SUM(J15:J32) | ... AB33: =SUM(AB15:AB32)
B35: הוצאות משתנות
B36: =IF(מיפוי!B38="","",מיפוי!B38) | C36: =IF(מיפוי!D38="","",מיפוי!D38) | E36: =C36 | G36: =E36 | I36: =G36 | K36: =I36 | M36: =K36 | O36: =M36 | Q36: =O36 | S36: =Q36 | U36: =S36 | W36: =U36 | Y36: =W36 | AA36: =SUM(C36,E36,G36,I36,K36,M36,O36,Q36,S36,U36,W36,Y36) | AB36: =SUM(D36,F36,H36,J36,L36,N36,P36,R36,T36,V36,X36,Z36)
B37: =IF(מיפוי!B39="","",מיפוי!B39) | C37: =IF(מיפוי!D39="","",מיפוי!D39) | E37: =C37 | G37: =E37 | I37: =G37 | K37: =I37 | M37: =K37 | O37: =M37 | Q37: =O37 | S37: =Q37 | U37: =S37 | W37: =U37 | Y37: =W37 | AA37: =SUM(C37,E37,G37,I37,K37,M37,O37,Q37,S37,U37,W37,Y37) | AB37: =SUM(D37,F37,H37,J37,L37,N37,P37,R37,T37,V37,X37,Z37)
B38: =IF(מיפוי!B40="","",מיפוי!B40) | C38: =IF(מיפוי!D40="","",מיפוי!D40) | E38: =C38 | G38: =E38 | I38: =G38 | K38: =I38 | M38: =K38 | O38: =M38 | Q38: =O38 | S38: =Q38 | U38: =S38 | W38: =U38 | Y38: =W38 | AA38: =SUM(C38,E38,G38,I38,K38,M38,O38,Q38,S38,U38,W38,Y38) | AB38: =SUM(D38,F38,H38,J38,L38,N38,P38,R38,T38,V38,X38,Z38)
B39: =IF(מיפוי!B41="","",מיפוי!B41) | C39: =IF(מיפוי!D41="","",מיפוי!D41) | E39: =C39 | G39: =E39 | I39: =G39 | K39: =I39 | M39: =K39 | O39: =M39 | Q39: =O39 | S39: =Q39 | U39: =S39 | W39: =U39 | Y39: =W39 | AA39: =SUM(C39,E39,G39,I39,K39,M39,O39,Q39,S39,U39,W39,Y39) | AB39: =SUM(D39,F39,H39,J39,L39,N39,P39,R39,T39,V39,X39,Z39)
B40: =IF(מיפוי!B42="","",מיפוי!B42) | C40: =IF(מיפוי!D42="","",מיפוי!D42) | E40: =C40 | G40: =E40 | I40: =G40 | K40: =I40 | M40: =K40 | O40: =M40 | Q40: =O40 | S40: =Q40 | U40: =S40 | W40: =U40 | Y40: =W40 | AA40: =SUM(C40,E40,G40,I40,K40,M40,O40,Q40,S40,U40,W40,Y40) | AB40: =SUM(D40,F40,H40,J40,L40,N40,P40,R40,T40,V40,X40,Z40)
B41: =IF(מיפוי!B43="","",מיפוי!B43) | C41: =IF(מיפוי!D43="","",מיפוי!D43) | E41: =C41 | G41: =E41 | I41: =G41 | K41: =I41 | M41: =K41 | O41: =M41 | Q41: =O41 | S41: =Q41 | U41: =S41 | W41: =U41 | Y41: =W41 | AA41: =SUM(C41,E41,G41,I41,K41,M41,O41,Q41,S41,U41,W41,Y41) | AB41: =SUM(D41,F41,H41,J41,L41,N41,P41,R41,T41,V41,X41,Z41)
B42: =IF(מיפוי!B44="","",מיפוי!B44) | C42: =IF(מיפוי!D44="","",מיפוי!D44) | E42: =C42 | G42: =E42 | I42: =G42 | K42: =I42 | M42: =K42 | O42: =M42 | Q42: =O42 | S42: =Q42 | U42: =S42 | W42: =U42 | Y42: =W42 | AA42: =SUM(C42,E42,G42,I42,K42,M42,O42,Q42,S42,U42,W42,Y42) | AB42: =SUM(D42,F42,H42,J42,L42,N42,P42,R42,T42,V42,X42,Z42)
...

Sheet עסק
B1: העסק — שכבה נפרדת לחלוטין | I1: 🏠 בית
B2: העסק מתנהל כאן במלואו. רק שורת "משכורת הבעלים" חוצה את הגבול אל תזרים המשפחה.
C4: =CHOOSE(MONTH(תזרים!C62),"ינו","פבר","מרץ","אפר","מאי","יונ","יול","אוג","ספט","אוק","נוב","דצמ") | D4: =CHOOSE(MONTH(תזרים!E62),"ינו","פבר","מרץ","אפר","מאי","יונ","יול","אוג","ספט","אוק","נוב","דצמ") | E4: =CHOOSE(MONTH(תזרים!G62),"ינו","פבר","מרץ","אפר","מאי","יונ","יול","אוג","ספט","אוק","נוב","דצמ") | F4: =CHOOSE(MONTH(תזרים!I62),"ינו","פבר","מרץ","אפר","מאי","יונ","יול","אוג","ספט","אוק","נוב","דצמ") | G4: =CHOOSE(MONTH(תזרים!K62),"ינו","פבר","מרץ","אפר","מאי","יונ","יול","אוג","ספט","אוק","נוב","דצמ") | H4: =CHOOSE(MONTH(תזרים!M62),"ינו","פבר","מרץ","אפר","מאי","יונ","יול","אוג","ספט","אוק","נוב","דצמ") | I4: =CHOOSE(MONTH(תזרים!O62),"ינו","פבר","מרץ","אפר","מאי","יונ","יול","אוג","ספט","אוק","נוב","דצמ") | J4: =CHOOSE(MONTH(תזרים!Q62),"ינו","פבר","מרץ","אפר","מאי","יונ","יול","אוג","ספט","אוק","נוב","דצמ") | K4: =CHOOSE(MONTH(תזרים!S62),"ינו","פבר","מרץ","אפר","מאי","יונ","יול","אוג","ספט","אוק","נוב","דצמ") | L4: =CHOOSE(MONTH(תזרים!U62),"ינו","פבר","מרץ","אפר","מאי","יונ","יול","אוג","ספט","אוק","נוב","דצמ") | M4: =CHOOSE(MONTH(תזרים!W62),"ינו","פבר","מרץ","אפר","מאי","יונ","יול","אוג","ספט","אוק","נוב","דצמ") | N4: =CHOOSE(MONTH(תזרים!Y62),"ינו","פבר","מרץ","אפר","מאי","יונ","יול","אוג","ספט","אוק","נוב","דצמ") | O4: סה"כ
B5: הכנסות תפעוליות | O5: =SUM(C5:N5)
B6: הוצאות קבועות של העסק | O6: =SUM(C6:N6)
B7: הוצאות משתנות של העסק | O7: =SUM(C7:N7)
B8: הפרשה למסים ומע"מ | O8: =SUM(C8:N8)
B9: ◄ רווח תפעולי | C9: =C5-C6-C7-C8 | D9: =D5-D6-D7-D8 | E9: =E5-E6-E7-E8 | F9: =F5-F6-F7-F8 | G9: =G5-G6-G7-G8 | H9: =H5-H6-H7-H8 | I9: =I5-I6-I7-I8 | J9: =J5-J6-J7-J8 | ... N9: =N5-N6-N7-N8 | O9: =SUM(C9:N9)
B10: משכורת בעלים — משיכה לבית | O10: =SUM(C10:N10)
B11: ◄ נשאר בעסק (אחרי משכורת) | C11: =C9-C10 | D11: =D9-D10 | E11: =E9-E10 | F11: =F9-F10 | G11: =G9-G10 | H11: =H9-H10 | I11: =I9-I10 | J11: =J9-J10 | ... N11: =N9-N10 | O11: =SUM(C11:N11)
B12: מצטבר בעסק | C12: =C11 | D12: =C12+D11 | E12: =D12+E11 | F12: =E12+F11 | G12: =F12+G11 | H12: =G12+H11 | I12: =H12+I11 | J12: =I12+J11 | K12: =J12+K11 | ... N12: =M12+N11
B13: ההפרדה: הוצאה עסקית לא נוגעת בתזרים הבית. שורה 10 — המשכורת — היא הצינור היחיד: נרשמת כאן כהוצאת עסק, ומופיעה אוטומטית כהכנסה בתזרים המשפחה.
B15: תכנית ההפרדה — הבית והעסק לא מתערבבים
B16: שכר קבוע לבית, בכל חודש
B17: יעד כרית עסקית (חודשי הוצאה) | C17: 3
B18: הוצאה חודשית ממוצעת בעסק | C18: =IFERROR((O6+O7+O8)/MAX(1,COUNT(C5:N5)),0)
B19: יעד כרית ₪ | C19: =C17*C18
B20: כרית בפועל (נשאר בעסק, מצטבר) | C20: =O9-O10
B22: =IF(N(C16)=0,"קבעו שכר חודשי קבוע לבית — זו ההפרדה החשובה ביותר. העסק משלם משכורת, לא כספומט.",IF(SUMPRODUCT((C10:N10>C16+50)*1)>0,"🔴 ב-"&SUMPRODUCT((C10:N10>C16+50)*1)&" חודשים נמשך מעבר לשכר הקבוע — הבית והעסק מתערבבים",IF(C20<C19,"🟡 השכר קבוע ✔ · הכרית העסקית עוד לא ביעד — חסר "&TEXT(C19-C20,"#,##0")&" ₪","🟢 הפרדה מלאה: שכר קבוע + כרית עסקית ביעד")))
B24: כללי ההפרדה: חשבון בנק נפרד · כרטיס נפרד · המשכורת עוברת בתאריך קבוע · הפרשה למס כל חודש (לא בהפתעה במקדמות) · אף הוצאה עסקית לא יוצאת מחשבון הבית.

Sheet סיכום שנתי
B1: סיכום שנתי | I1: 🏠 בית
B2: מתעדכן לבד מהתזרים. זה הדף שמסתכלים עליו ביחד.
B4: הכנסה שנתית | D4: הוצאה שנתית | F4: תזרים נטו | H4: שיעור חיסכון
B5: =IF(תזרים!AB12=0,תזרים!AA12,תזרים!AB12) | D5: =IF(תזרים!AB55=0,תזרים!AA55,תזרים!AB55) | F5: =IF(תזרים!AB12=0,תזרים!AA56,תזרים!AB56) | H5: =IFERROR(IF(תזרים!AB12=0,תזרים!AA56/תזרים!AA12,תזרים!AB56/תזרים!AB12),"")
B7: רמזור בריאות תזרימית
B8: מדד | E8: הערך שלכם | G8: יעד | H8: סטטוס
B9: שיעור חיסכון | E9: =IFERROR(IF(תזרים!AB12=0,תזרים!AA56/תזרים!AA12,תזרים!AB56/תזרים!AB12),0) | G9: ≥ 10% | H9: =IF(E9>=0.1,"🟢 תקין",IF(E9>=0.03,"🟡 גבולי","🔴 דורש טיפול"))
B10: נטל הלוואות מההכנסה | E10: =IFERROR((חובות!E16+חובות!E34)/(IF(תזרים!AB12=0,תזרים!AA12,תזרים!AB12)/12),0) | G10: ≤ 35% | H10: =IF(E10<=0.35,"🟢 תקין",IF(E10<=0.45,"🟡 גבולי","🔴 דורש טיפול"))
B11: קבועות מההכנסה | E11: =IFERROR(IF(תזרים!AB12=0,תזרים!AA33/תזרים!AA12,תזרים!AB33/תזרים!AB12),0) | G11: ≤ 55% | H11: =IF(E11<=0.55,"🟢 תקין",IF(E11<=0.65,"🟡 גבולי","🔴 דורש טיפול"))
B13: לאן הולך הכסף — שנתי, תכנון מול ביצוע
B14: קטגוריה | E14: תכנון | F14: ביצוע | G14: פער | H14: % מהכנסה
B15: =IF(תזרים!B15="","",תזרים!B15) | E15: =IF(תזרים!B15="","",תזרים!AA15) | F15: =IF(תזרים!B15="","",תזרים!AB15) | G15: =IF(OR(תזרים!B15="",F15=0),"",F15-E15) | H15: =IF(תזרים!B15="","",IFERROR(IF(F15=0,E15,F15)/IF(תזרים!AB12=0,תזרים!AA12,תזרים!AB12),""))
B16: =IF(תזרים!B16="","",תזרים!B16) | E16: =IF(תזרים!B16="","",תזרים!AA16) | F16: =IF(תזרים!B16="","",תזרים!AB16) | G16: =IF(OR(תזרים!B16="",F16=0),"",F16-E16) | H16: =IF(תזרים!B16="","",IFERROR(IF(F16=0,E16,F16)/IF(תזרים!AB12=0,תזרים!AA12,תזרים!AB12),""))
B17: =IF(תזרים!B17="","",תזרים!B17) | E17: =IF(תזרים!B17="","",תזרים!AA17) | F17: =IF(תזרים!B17="","",תזרים!AB17) | G17: =IF(OR(תזרים!B17="",F17=0),"",F17-E17) | H17: =IF(תזרים!B17="","",IFERROR(IF(F17=0,E17,F17)/IF(תזרים!AB12=0,תזרים!AA12,תזרים!AB12),""))
B18: =IF(תזרים!B18="","",תזרים!B18) | E18: =IF(תזרים!B18="","",תזרים!AA18) | F18: =IF(תזרים!B18="","",תזרים!AB18) | G18: =IF(OR(תזרים!B18="",F18=0),"",F18-E18) | H18: =IF(תזרים!B18="","",IFERROR(IF(F18=0,E18,F18)/IF(תזרים!AB12=0,תזרים!AA12,תזרים!AB12),""))
B19: =IF(תזרים!B19="","",תזרים!B19) | E19: =IF(תזרים!B19="","",תזרים!AA19) | F19: =IF(תזרים!B19="","",תזרים!AB19) | G19: =IF(OR(תזרים!B19="",F19=0),"",F19-E19) | H19: =IF(תזרים!B19="","",IFERROR(IF(F19=0,E19,F19)/IF(תזרים!AB12=0,תזרים!AA12,תזרים!AB12),""))
B20: =IF(תזרים!B20="","",תזרים!B20) | E20: =IF(תזרים!B20="","",תזרים!AA20) | F20: =IF(תזרים!B20="","",תזרים!AB20) | G20: =IF(OR(תזרים!B20="",F20=0),"",F20-E20) | H20: =IF(תזרים!B20="","",IFERROR(IF(F20=0,E20,F20)/IF(תזרים!AB12=0,תזרים!AA12,תזרים!AB12),""))
B21: =IF(תזרים!B21="","",תזרים!B21) | E21: =IF(תזרים!B21="","",תזרים!AA21) | F21: =IF(תזרים!B21="","",תזרים!AB21) | G21: =IF(OR(תזרים!B21="",F21=0),"",F21-E21) | H21: =IF(תזרים!B21="","",IFERROR(IF(F21=0,E21,F21)/IF(תזרים!AB12=0,תזרים!AA12,תזרים!AB12),""))
B22: =IF(תזרים!B22="","",תזרים!B22) | E22: =IF(תזרים!B22="","",תזרים!AA22) | F22: =IF(תזרים!B22="","",תזרים!AB22) | G22: =IF(OR(תזרים!B22="",F22=0),"",F22-E22) | H22: =IF(תזרים!B22="","",IFERROR(IF(F22=0,E22,F22)/IF(תזרים!AB12=0,תזרים!AA12,תזרים!AB12),""))
B23: =IF(תזרים!B23="","",תזרים!B23) | E23: =IF(תזרים!B23="","",תזרים!AA23) | F23: =IF(תזרים!B23="","",תזרים!AB23) | G23: =IF(OR(תזרים!B23="",F23=0),"",F23-E23) | H23: =IF(תזרים!B23="","",IFERROR(IF(F23=0,E23,F23)/IF(תזרים!AB12=0,תזרים!AA12,תזרים!AB12),""))
B24: =IF(תזרים!B24="","",תזרים!B24) | E24: =IF(תזרים!B24="","",תזרים!AA24) | F24: =IF(תזרים!B24="","",תזרים!AB24) | G24: =IF(OR(תזרים!B24="",F24=0),"",F24-E24) | H24: =IF(תזרים!B24="","",IFERROR(IF(F24=0,E24,F24)/IF(תזרים!AB12=0,תזרים!AA12,תזרים!AB12),""))
B25: =IF(תזרים!B25="","",תזרים!B25) | E25: =IF(תזרים!B25="","",תזרים!AA25) | F25: =IF(תזרים!B25="","",תזרים!AB25) | G25: =IF(OR(תזרים!B25="",F25=0),"",F25-E25) | H25: =IF(תזרים!B25="","",IFERROR(IF(F25=0,E25,F25)/IF(תזרים!AB12=0,תזרים!AA12,תזרים!AB12),""))
B26: =IF(תזרים!B26="","",תזרים!B26) | E26: =IF(תזרים!B26="","",תזרים!AA26) | F26: =IF(תזרים!B26="","",תזרים!AB26) | G26: =IF(OR(תזרים!B26="",F26=0),"",F26-E26) | H26: =IF(תזרים!B26="","",IFERROR(IF(F26=0,E26,F26)/IF(תזרים!AB12=0,תזרים!AA12,תזרים!AB12),""))
B27: =IF(תזרים!B27="","",תזרים!B27) | E27: =IF(תזרים!B27="","",תזרים!AA27) | F27: =IF(תזרים!B27="","",תזרים!AB27) | G27: =IF(OR(תזרים!B27="",F27=0),"",F27-E27) | H27: =IF(תזרים!B27="","",IFERROR(IF(F27=0,E27,F27)/IF(תזרים!AB12=0,תזרים!AA12,תזרים!AB12),""))
B28: =IF(תזרים!B28="","",תזרים!B28) | E28: =IF(תזרים!B28="","",תזרים!AA28) | F28: =IF(תזרים!B28="","",תזרים!AB28) | G28: =IF(OR(תזרים!B28="",F28=0),"",F28-E28) | H28: =IF(תזרים!B28="","",IFERROR(IF(F28=0,E28,F28)/IF(תזרים!AB12=0,תזרים!AA12,תזרים!AB12),""))
B29: =IF(תזרים!B29="","",תזרים!B29) | E29: =IF(תזרים!B29="","",תזרים!AA29) | F29: =IF(תזרים!B29="","",תזרים!AB29) | G29: =IF(OR(תזרים!B29="",F29=0),"",F29-E29) | H29: =IF(תזרים!B29="","",IFERROR(IF(F29=0,E29,F29)/IF(תזרים!AB12=0,תזרים!AA12,תזרים!AB12),""))
B30: =IF(תזרים!B30="","",תזרים!B30) | E30: =IF(תזרים!B30="","",תזרים!AA30) | F30: =IF(תזרים!B30="","",תזרים!AB30) | G30: =IF(OR(תזרים!B30="",F30=0),"",F30-E30) | H30: =IF(תזרים!B30="","",IFERROR(IF(F30=0,E30,F30)/IF(תזרים!AB12=0,תזרים!AA12,תזרים!AB12),""))
B31: =IF(תזרים!B31="","",תזרים!B31) | E31: =IF(תזרים!B31="","",תזרים!AA31) | F31: =IF(תזרים!B31="","",תזרים!AB31) | G31: =IF(OR(תזרים!B31="",F31=0),"",F31-E31) | H31: =IF(תזרים!B31="","",IFERROR(IF(F31=0,E31,F31)/IF(תזרים!AB12=0,תזרים!AA12,תזרים!AB12),""))
B32: =IF(תזרים!B32="","",תזרים!B32) | E32: =IF(תזרים!B32="","",תזרים!AA32) | F32: =IF(תזרים!B32="","",תזרים!AB32) | G32: =IF(OR(תזרים!B32="",F32=0),"",F32-E32) | H32: =IF(תזרים!B32="","",IFERROR(IF(F32=0,E32,F32)/IF(תזרים!AB12=0,תזרים!AA12,תזרים!AB12),""))
B33: =IF(תזרים!B36="","",תזרים!B36) | E33: =IF(תזרים!B36="","",תזרים!AA36) | F33: =IF(תזרים!B36="","",תזרים!AB36) | G33: =IF(OR(תזרים!B36="",F33=0),"",F33-E33) | H33: =IF(תזרים!B36="","",IFERROR(IF(F33=0,E33,F33)/IF(תזרים!AB12=0,תזרים!AA12,תזרים!AB12),""))
B34: =IF(תזרים!B37="","",תזרים!B37) | E34: =IF(תזרים!B37="","",תזרים!AA37) | F34: =IF(תזרים!B37="","",תזרים!AB37) | G34: =IF(OR(תזרים!B37="",F34=0),"",F34-E34) | H34: =IF(תזרים!B37="","",IFERROR(IF(F34=0,E34,F34)/IF(תזרים!AB12=0,תזרים!AA12,תזרים!AB12),""))
B35: =IF(תזרים!B38="","",תזרים!B38) | E35: =IF(תזרים!B38="","",תזרים!AA38) | F35: =IF(תזרים!B38="","",תזרים!AB38) | G35: =IF(OR(תזרים!B38="",F35=0),"",F35-E35) | H35: =IF(תזרים!B38="","",IFERROR(IF(F35=0,E35,F35)/IF(תזרים!AB12=0,תזרים!AA12,תזרים!AB12),""))
B36: =IF(תזרים!B39="","",תזרים!B39) | E36: =IF(תזרים!B39="","",תזרים!AA39) | F36: =IF(תזרים!B39="","",תזרים!AB39) | G36: =IF(OR(תזרים!B39="",F36=0),"",F36-E36) | H36: =IF(תזרים!B39="","",IFERROR(IF(F36=0,E36,F36)/IF(תזרים!AB12=0,תזרים!AA12,תזרים!AB12),""))
B37: =IF(תזרים!B40="","",תזרים!B40) | E37: =IF(תזרים!B40="","",תזרים!AA40) | F37: =IF(תזרים!B40="","",תזרים!AB40) | G37: =IF(OR(תזרים!B40="",F37=0),"",F37-E37) | H37: =IF(תזרים!B40="","",IFERROR(IF(F37=0,E37,F37)/IF(תזרים!AB12=0,תזרים!AA12,תזרים!AB12),""))
B38: =IF(תזרים!B41="","",תזרים!B41) | E38: =IF(תזרים!B41="","",תזרים!AA41) | F38: =IF(תזרים!B41="","",תזרים!AB41) | G38: =IF(OR(תזרים!B41="",F38=0),"",F38-E38) | H38: =IF(תזרים!B41="","",IFERROR(IF(F38=0,E38,F38)/IF(תזרים!AB12=0,תזרים!AA12,תזרים!AB12),""))
B39: =IF(תזרים!B42="","",תזרים!B42) | E39: =IF(תזרים!B42="","",תזרים!AA42) | F39: =IF(תזרים!B42="","",תזרים!AB42) | G39: =IF(OR(תזרים!B42="",F39=0),"",F39-E39) | H39: =IF(תזרים!B42="","",IFERROR(IF(F39=0,E39,F39)/IF(תזרים!AB12=0,תזרים!AA12,תזרים!AB12),""))
B40: =IF(תזרים!B43="","",תזרים!B43) | E40: =IF(תזרים!B43="","",תזרים!AA43) | F40: =IF(תזרים!B43="","",תזרים!AB43) | G40: =IF(OR(תזרים!B43="",F40=0),"",F40-E40) | H40: =IF(תזרים!B43="","",IFERROR(IF(F40=0,E40,F40)/IF(תזרים!AB12=0,תזרים!AA12,תזרים!AB12),""))
B41: =IF(תזרים!B44="","",תזרים!B44) | E41: =IF(תזרים!B44="","",תזרים!AA44) | F41: =IF(תזרים!B44="","",תזרים!AB44) | G41: =IF(OR(תזרים!B44="",F41=0),"",F41-E41) | H41: =IF(תזרים!B44="","",IFERROR(IF(F41=0,E41,F41)/IF(תזרים!AB12=0,תזרים!AA12,תזרים!AB12),""))
B42: =IF(תזרים!B45="","",תזרים!B45) | E42: =IF(תזרים!B45="","",תזרים!AA45) | F42: =IF(תזרים!B45="","",תזרים!AB45) | G42: =IF(OR(תזרים!B45="",F42=0),"",F42-E42) | H42: =IF(תזרים!B45="","",IFERROR(IF(F42=0,E42,F42)/IF(תזרים!AB12=0,תזרים!AA12,תזרים!AB12),""))
B43: =IF(תזרים!B46="","",תזרים!B46) | E43: =IF(תזרים!B46="","",תזרים!AA46) | F43: =IF(תזרים!B46="","",תזרים!AB46) | G43: =IF(OR(תזרים!B46="",F43=0),"",F43-E43) | H43: =IF(תזרים!B46="","",IFERROR(IF(F43=0,E43,F43)/IF(תזרים!AB12=0,תזרים!AA12,תזרים!AB12),""))
...

Sheet תובנות
B1: =IF(שאלון!C6="","תמונת מצב ותוכנית פעולה","תמונת מצב ותוכנית פעולה — "&שאלון!C6&IF(שאלון!D6="",""," ו"&שאלון!D6)) | I1: 🏠 בית
B2: העמוד שמסתכלים עליו ביחד. הכל מתעדכן לבד מכל שאר הקובץ.
B4: שווי נקי | E4: תזרים חודשי נטו (ממוצע) | H4: % מהמטרות שממומן
B5: =מאזן!B28 | E5: =IFERROR(IF(תזרים!$AC$2>0,תזרים!AB56/תזרים!$AC$2,תזרים!AA56/12),0) | H5: =IFERROR('מטרות ויעדים'!K17/'מטרות ויעדים'!J17,"")
B7: בריאות פיננסית — רמזור
B8: מדד | E8: הערך שלכם | G8: יעד מומלץ | H8: סטטוס
B9: מינוף — חוב מהנכסים | E9: =IFERROR(מאזן!C25/מאזן!C17,0) | G9: ≤ 50% | H9: =IF(E9<=0.5,"🟢 תקין",IF(E9<=0.7,"🟡 לתשומת לב","🔴 דורש טיפול"))
B10: נטל החזרים מההכנסה | E10: =IFERROR((חובות!E16+חובות!E34)/MAX(1,IF(תזרים!$AC$2>0,תזרים!AB12/תזרים!$AC$2,תזרים!AA12/12)),0) | G10: ≤ 35% | H10: =IF(E10<=0.35,"🟢 תקין",IF(E10<=0.45,"🟡 לתשומת לב","🔴 דורש טיפול"))
B11: עלות דיור מההכנסה | E11: =IFERROR((IF(תזרים!AB15=0,תזרים!AA15,תזרים!AB15)/12)/(IF(תזרים!AB12=0,תזרים!AA12,תזרים!AB12)/12),0) | G11: ≤ 30% | H11: =IF(E11<=0.3,"🟢 תקין",IF(E11<=0.4,"🟡 לתשומת לב","🔴 דורש טיפול"))
B12: שיעור חיסכון | E12: =IFERROR(IF(תזרים!AB12=0,תזרים!AA56/תזרים!AA12,תזרים!AB56/תזרים!AB12),0) | G12: ≥ 15% | H12: =IF(E12>=0.15,"🟢 תקין",IF(E12>=0.08,"🟡 לתשומת לב","🔴 דורש טיפול"))
B13: כרית חירום (חודשים) | E13: =IFERROR((N(מאזן!C6)+N(מאזן!C7))/MAX(1,IF(תזרים!$AC$2>0,תזרים!AB55/תזרים!$AC$2,תזרים!AA55/12)),0) | G13: ≥ 6 | H13: =IF(E13>=6,"🟢 תקין",IF(E13>=3,"🟡 לתשומת לב","🔴 דורש טיפול"))
B14: מימון המטרות | E14: =IFERROR('מטרות ויעדים'!K17/'מטרות ויעדים'!J17,0) | G14: ככל שיותר — יותר | H14: =IF(E14>=0.5,"🟢 תקין",IF(E14>=0.25,"🟡 לתשומת לב","🔴 דורש טיפול"))
B16: מה עושים עכשיו — לפי סדר עדיפות
B17: 1 | C17: =IF((6*MAX(1,IF(תזרים!$AC$2>0,תזרים!AB55/תזרים!$AC$2,תזרים!AA55/12)))-(N(מאזן!C6)+N(מאזן!C7))>0,"קרן חירום — להשלים עוד "&TEXT(6*IF(תזרים!$AC$2>0,תזרים!AB55/תזרים!$AC$2,תזרים!AA55/12)-(N(מאזן!C6)+N(מאזן!C7)),"#,##0")&" ₪ (היעד: 6 חודשי הוצאה)","קרן חירום — ✔ תקינה")
B18: 2 | C18: =IF(חובות!C16=0,"הלוואות — אין ✔",IF(חובות!J10>0,"הלוואות — לבדוק איחוד: חיסכון אפשרי של "&TEXT(חובות!J10,"#,##0")&" ₪ בחודש","הלוואות — קיימות; לבדוק ריביות מול הבנק"))
B19: 3 | C19: =IF('מטרות ויעדים'!M17=0,"מטרות — מלאו את עמוד המטרות (דרך השאלון)",IF('מטרות ויעדים'!N17+50<'מטרות ויעדים'!M17,"מטרות — להשלים הקצאה של "&TEXT('מטרות ויעדים'!M17-'מטרות ויעדים'!N17,"#,##0")&" ₪ בחודש","מטרות — ✔ מוקצות במלואן"))
B20: 4 | C20: =IF(IFERROR(IF(תזרים!AB12=0,תזרים!AA56/תזרים!AA12,תזרים!AB56/תזרים!AB12),0)<0.15,"שיעור חיסכון — כרגע "&TEXT(IFERROR(IF(תזרים!AB12=0,תזרים!AA56/תזרים!AA12,תזרים!AB56/תזרים!AB12),0),"0%")&" — לכוון ל-15-20%","שיעור חיסכון — ✔ בריא")
B21: 5 | C21: =IF(N(מיפוי!L17)>0,"מנויים — לעבור על הרשימה: "&TEXT(מיפוי!L17,"#,##0")&" ₪ בחודש. מה כבר לא בשימוש?","מנויים — טרם הוזנו במיפוי")
B23: ✔ = תקין. כל שורה עם מספר = הפעולה הבאה והפער המדויק. מתעדכן לבד מהמיפוי, מהתזרים, מהמאזן ומהמטרות.

Sheet יומן ליווי
B1: יומן ליווי — 5 פגישות | I1: 🏠 בית
B2: מה סוכם, מה המשימות, ומה לקחתם מכל פגישה.
B3: תאריך תחילת הליווי (מדף הבית): | C3: =IF(תזרים!C2="","",תזרים!C62) | D3: חודש ליווי נוכחי: | E3: =IF(C3="","",(YEAR(TODAY())-YEAR(C3))*12+MONTH(TODAY())-MONTH(C3)+1)
B5: פגישה 1
B6: תאריך: | D6: נושא:
B7: מה סוכם:
B9: משימות עד הפגישה הבאה:
B11: מה לקחנו מהפגישה (הלקוח):
B14: פגישה 2
B15: תאריך: | D15: נושא:
B16: מה סוכם:
B18: משימות עד הפגישה הבאה:
B20: מה לקחנו מהפגישה (הלקוח):
B23: פגישה 3
B24: תאריך: | D24: נושא:
B25: מה סוכם:
B27: משימות עד הפגישה הבאה:
B29: מה לקחנו מהפגישה (הלקוח):
B32: פגישה 4
B33: תאריך: | D33: נושא:
B34: מה סוכם:
B36: משימות עד הפגישה הבאה:
B38: מה לקחנו מהפגישה (הלקוח):
B41: פגישה 5
B42: תאריך: | D42: נושא:
B43: מה סוכם:
B45: משימות עד הפגישה הבאה:
B47: מה לקחנו מהפגישה (הלקוח):

Sheet מחשבונים
B1: מחשבונים וכלים | I1: 🏠 בית
B2: כלי עזר לפגישה. הנתונים נמשכים מהמאזן ומהחובות איפה שאפשר.
B4: שווי הנכס ו-LTV — הגדלת משכנתא | E4: מחשבון ביטוח חיים — כמה כיסוי באמת צריך
B5: שווי הנכס היום (מהמאזן) | C5: =N(מאזן!C14) | F5: =IF(שאלון!C6="","בן/בת זוג 1",שאלון!C6) | G5: =IF(שאלון!D6="","בן/בת זוג 2",שאלון!D6)
B6: יתרת המשכנתא (מהמאזן) | C6: =N(מאזן!C21) | E6: ① הכנסה חודשית שנפסקת
B7: ◄ LTV — אחוז המימון הנוכחי | C7: =IFERROR(C6/C5,0) | E7: (−) הכנסות שיישארו לשארים
B8: תקרת מימון להגדלה | C8: 0.5 | E8: ◄ הפער החודשי | F8: =N(F6)-N(F7) | G8: =N(G6)-N(G7)
B9: ◄ ניתן להגדיל עוד | C9: =MAX(0,C5*C8-C6) | E9: שנים לכיסוי הפער | F9: 20 | G9: 20
B10: כל מטרה עד 50% · שיפור דיור עד 70% · דירה יחידה עד 75%. | E10: ריבית ריאלית להיוון | F10: 0.03 | G10: 0.03
E11: ◄ הון להשלמת הכנסה (מהוון) | F11: =IF(N(F8)<=0,0,IFERROR(-PV(F10/12,F9*12,F8),N(F8)*N(F9)*12)) | G11: =IF(N(G8)<=0,0,IFERROR(-PV(G10/12,G9*12,G8),N(G8)*N(G9)*12))
B12: מחשבון מחזור משכנתא | E12: ② חד-פעמי: סילוק חובות לא-מבוטחים
B13: יתרת משכנתא | C13: =N(מאזן!C21) | E13: ② חד-פעמי: התארגנות ושנה ראשונה
B14: ריבית שנתית נוכחית | C14: 0.052 | E14: ② חד-פעמי: אחר (רכב, לימודים, מעבר)
B15: שנים שנותרו | C15: 20 | E15: סה"כ חד-פעמי | F15: =SUM(F12:F14) | G15: =SUM(G12:G14)
B16: ריבית שנתית חדשה | C16: 0.043 | E16: (−) נכסים נזילים והשקעות | F16: =N(מאזן!C6)+N(מאזן!C7)+N(מאזן!C8)+N(מאזן!C9)+N(מאזן!C10)+N(מאזן!C11) | G16: =N(מאזן!C6)+N(מאזן!C7)+N(מאזן!C8)+N(מאזן!C9)+N(מאזן!C10)+N(מאזן!C11)
B17: החזר חודשי נוכחי | C17: =IFERROR(-PMT(C14/12,C15*12,C13),0) | E17: (−) ביטוח חיים קיים (מהשאלון) | F17: =N(שאלון!C35) | G17: =N(שאלון!D35)
B18: החזר חודשי אחרי מחזור | C18: =IFERROR(-PMT(C16/12,C15*12,C13),0) | E18: ◄◄ כיסוי נדרש בריסק | F18: =MAX(0,N(F11)+N(F15)-N(F16)-N(F17)) | G18: =MAX(0,N(G11)+N(G15)-N(G16)-N(G17))
B19: ◄ חיסכון חודשי | C19: =C17-C18 | E19: =IF(F6+G6=0,"מלאו את ההכנסה שנפסקת ומה שיישאר — והפער יחושב לבד",IF(F18+G18=0,"🟢 הפער החודשי מכוסה — השארים והנכסים מספיקים","🔴 כיסוי נדרש: "&F5&" — "&TEXT(F18,"#,##0")&" ₪ · "&G5&" — "&TEXT(G18,"#,##0")&" ₪. לתמחר ריסק טהור"))
B20: ◄ חיסכון על כל התקופה | C20: =C19*C15*12
B21: חישוב עקרוני במסלול אחד — כלי לשיחה, לא לביצוע. | E21: עזר: כמה קרן הפנסיה כבר מכסה (סכום בסיכון)
E22: מקדם כיסוי מוות (מהדוח השנתי)
B23: מחשבון יכולת רכישת נכס | E23: שכר מבוטח לפנסיה
B24: הון עצמי זמין | E24: צבירה בקרן (מהמאזן) | F24: =N(מאזן!C12) | G24: =N(מאזן!C13)
B25: אחוז מימון מקסימלי | C25: 0.75 | E25: ◄ סכום בסיכון — הכיסוי מהפנסיה | F25: =MAX(0,N(F22)*N(F23)*0.6-N(F24)) | G25: =MAX(0,N(G22)*N(G23)*0.6-N(G24))
B26: ריבית משכנתא שנתית | C26: 0.05
B27: תקופה (שנים) | C27: 25 | E27: ההיגיון: מחשבים כמה חודש-בחודש יחסר לשארים (אחרי קצבת שארים והכנסת בן הזוג), מהוונים את הפער לכל השנים, מוסיפים צרכים חד-פעמיים — ומנכים את מה שכבר יש. "סכום בסיכון" למטה מראה כמה כיסוי מובנה כבר קיים בקרן הפנסיה (מקדם × שכר × 60% − צבירה) — עוזר לדייק את שורת ההכנסות שיישארו.
B28: ◄ מחיר נכס מקסימלי | C28: =IFERROR(C24/(1-C25),0)
B29: סכום המשכנתא | C29: =C28*C25
B30: החזר חודשי צפוי | C30: =IFERROR(-PMT(C26/12,C27*12,C29),0)
B31: ◄ נטל מההכנסה החודשית | C31: =IFERROR(C30/MAX(1,IF(תזרים!$AC$2>0,תזרים!AB12/תזרים!$AC$2,תזרים!AA12/12)),0) | E31: מיפוי ביטוחים משפחתי — מי מכוסה במה
B32: דירה ראשונה עד 75% מימון · נטל החזר בריא: עד 30-35% מההכנסה נטו. | E32: בן משפחה | F32: ביטוח בריאות (חברה) | G32: ביטוחים נוספים | H32: פרמיה חודשית
E33: =IF(שאלון!C6="","בן/בת זוג 1",שאלון!C6)
E34: =IF(שאלון!D6="","בן/בת זוג 2",שאלון!D6)
E35: ילד/ה 1
E36: ילד/ה 2
E37: ילד/ה 3
E38: ילד/ה 4
E39: סה"כ פרמיות | H39: =SUM(H33:H38)
E41: שמות ההורים מתעדכנים מהשאלון. להשוות את סה"כ הפרמיות מול שורת הביטוחים במיפוי — פערים = כפל ביטוח או חוסר.
